Workbook
Name DEX: [1]主要情况!$G$10
Name STR: [1]主要情况!$G$8
Name 阿兰寇拉: 数据表!#REF!
Name 阿斯莫: 数据表!#REF!
Name 矮人: 数据表!#REF!
Name 斑猫人: 数据表!#REF!
Name 半精灵: 数据表!#REF!
Name 半人马: 数据表!#REF!
Name 半身人: 数据表!#REF!
Name 半兽人: 数据表!#REF!
Name 匕首: 装备!$O$5
Name 匕首伤害: 装备!#REF!
Name 鞭: 装备!$O$35
Name 鞭伤害: 装备!#REF!
Name 标枪: 装备!$O$8
Name 标枪伤害: 装备!#REF!
Name 捕网: 装备!$O$40
Name 捕网伤害: 装备!#REF!
Name 吹箭筒: 装备!$O$36
Name 吹箭筒伤害: 装备!#REF!
Name 纯种蛇人: 数据表!#REF!
Name 刺剑: 装备!$O$29
Name 刺剑伤害: 装备!#REF!
Name 地精: 数据表!#REF!
Name 钉头锤: 装备!$O$27
Name 钉头锤伤害: 装备!#REF!
Name 短棒: 装备!$O$4
Name 短棒伤害: 装备!#REF!
Name 短弓: 装备!$O$16
Name 短弓伤害: 装备!#REF!
Name 短剑: 装备!$O$31
Name 短剑伤害: 装备!#REF!
Name 飞镖: 装备!$O$15
Name 飞镖伤害: 装备!#REF!
Name 费尔伯格人: 数据表!#REF!
Name 歌利亚: 数据表!#REF!
Name 狗头人: 数据表!#REF!
Name 化兽者: 数据表!#REF!
Name 幻身灵: 数据表!#REF!
Name 吉斯人: 数据表!#REF!
Name 戟: 装备!$O$23
Name 戟伤害: 装备!#REF!
Name 精灵: 数据表!#REF!
Name 巨棒: 装备!$O$6
Name 巨棒伤害: 装备!#REF!
Name 巨锤: 装备!$O$26
Name 巨锤伤害: 装备!#REF!
Name 巨斧: 装备!$O$21
Name 巨斧伤害: 装备!#REF!
Name 巨剑: 装备!$O$22
Name 巨剑伤害: 装备!#REF!
Name 离梦人: 数据表!#REF!
Name 镰刀: 装备!$O$12
Name 镰刀伤害: 装备!#REF!
Name 链枷: 装备!$O$19
Name 链枷伤害: 装备!#REF!
Name 龙裔: 数据表!#REF!
Name 矛: 装备!$O$13
Name 矛伤害: 装备!#REF!
Name 牛头人: 数据表!#REF!

Sheet 背景
A1: 人物背景 Background
B3: 角色名 | E3: 诺菲雅 | Q3: 个性 | U3: 对事物的诞生与逝去，激烈的情感充满好奇
B4: 玩家 | E4: 霞秋羽 | U4: 每天都要尽可能的注视日升日落来见证时间的流逝
B5: 故乡 | E5: 星界 | Q5: 理念 | U5: 在这片陌生的土地上寻找对抗虚无的答案
B6: 背景 | E6: 远行者 | Q6: 羁绊 | U6: 我为这片美丽而神奇的新土地而着迷。
Q7: 缺陷 | U7: 我假装不懂这些人当地的语言以避免我不希望的交流。
B8: 年龄 | E8: 345 | I8: 发型 | L8: 高马尾
B9: 性别 | E9: 女 | I9: 发色 | L9: 淡灰色 | Q9: 人物衣装 外貌描述 | U9: 眼底闪烁着细碎的星光，情绪平静时像静谧的星空，激动时会流转起微光。平日里用发带束起高马尾，穿着一身方便行动的白色轻型皮甲，腰间挂着一把长剑和腰包。
B10: 身高 | E10: 176cm | I10: 肤色 | L10: 白
B11: 体重 | E11: 56kg | I11: 瞳色 | L11: 银蓝色
Q12: 背景特性 | U12: 众目焦点AllEyesonYou。你的口音，言谈举止，措辞风格甚至你的外表都表明你就是一个异乡人。无论你走到哪里，好奇的目光总会伴随着你。虽然这有些令人讨厌，但是也让你得以对那些感兴趣的学者们，和那些对远方好奇希望听你述说家乡故事之人的好感。与其他民众不同，你可以运用这种关注力为自己或旅伴们亲近想要接触之人。那些贵族领主、学者、商人望族等等可能会有兴趣听你那些有关远方故乡和人民的故事。
B13: 语言
B14: 通用语 | I14: 精灵语
B15: 天界语 | I15: 木族语
Q18: 背景故事 | U18: 我出生在星光位面那片银色的虚空里，那里没有日出日落，没有四季更迭，万物永恒不老，时间像一条静止的河 —— 我在那里生活了 345 年，看着同胞们在永恒的沉思里慢慢麻木，看着星界的光永远明亮却毫无温度。 我开始厌倦这种 “没有终点的存在”：没有成长，没有离别，没有 “完成一件事” 的喜悦，连生命本身都因为永恒而失去了重量。我想知道 “时间流逝” 是什么感觉，想看看会枯萎的花、会老去的人、会被黑夜吞噬的夕阳 —— 于是我背着竖琴，以 “远行者” 的身份，踏上了前往费伦大陆的旅途。 来到这片陌生的土地后，我找到了对抗虚无的方式：每天清晨追着日出，傍晚守着日落，用这个仪式来标记时间的流逝，证明 “我真的在活着”。 我着迷于费伦的一切：春日的樱花会在一夜之间绽放又凋零，凡人会为了一句誓言奔赴生死，篝火会在黎明前熄灭却留下温暖的余温 —— 这些都是星界永远不会有的 “真实”。我不想卷入琐碎的纷争，只想安静地做一个观察者，记录下所有短暂却炽热的瞬间。 但我也知道，我的旅途不止于此，我也不可能永远只是一个观察者，在这片陌生的土地上，或许我会找到属于我的友谊与羁绊。
B19: 熟练工具
B20: 竖琴
B25: 人物形象

Sheet 数据表
B1: 法术书 | C1: 专注 | D1: 仪式 | E1: 准备栏 | I1: 仪 | J1: 专 | M1: 1 | N1: 2 | O1: 3 | P1: 4 | Q1: 5 | R1: 6 | S1: 7 | T1: 8 | U1: 9 | V1: 10 | W1: 11 | X1: 12 | Y1: 13 | Z1: 14 | AA1: 15 | AB1: 16 | AC1: 17 | AD1: 18 | AE1: 19 | AF1: 20 | AK1: 戏法 | AL1: 0 | AO1: 物品效果 | AP1: 物品名称 | AQ1: 算盘 | AR1: - | AS1: 2gp | AT1: 2 | AU1: 物品重量 | AW1: 语言
A2: 1 | B2: =IF(#REF!="","",#REF!) -> #REF! | C2: =IFERROR(VLOOKUP(B2,#REF!,5,FALSE),"") | D2: =IFERROR(VLOOKUP(B2,#REF!,4,FALSE),"") | E2: 1 | F2: =B2 -> #REF! | H2: =IF(#REF!<>"",#REF!,"") -> #REF! | I2: =IF(VLOOKUP(H2,#REF!,4,0)="√",1,0) -> #REF! | J2: =IF(VLOOKUP(H2,#REF!,5,0)="√",1,0) -> #REF! | L2: 吟游诗人 | M2: 4 | N2: 5 | O2: 6 | P2: 7 | Q2: 8 | R2: 9 | S2: 10 | T2: 11 | U2: 12 | V2: 14 | W2: 15 | X2: 15 | Y2: 16 | Z2: 18 | AA2: 19 | AB2: 19 | AC2: 20 | AD2: 22 | AE2: 22 | AF2: 22 | AK2: 1环 | AL2: 1 | AO2: =IF(ISBLANK(#REF!),,INDEX(AR1:AT149,MATCH(#REF!&"*",AQ1:AQ149,0),1)) -> #REF! | AP2: =IF(ISBLANK(#REF!),,INDEX(AQ1:AT149,MATCH(#REF!&"*",AQ1:AQ149,0),1)) -> #REF! | AQ2: 强酸_小瓶 | AR2: 你可以用一个动作将这小瓶液体泼溅到你身边 5尺内的一个生物身上，或是将小瓶投到至多 20 尺远的地方，并利用冲击打破它。两种情况都可以视为对一个生物或物件发动一次远程攻击，并将强酸视为一件临时武器。命中时，目标受到 2d6点强酸伤害。 | AS2: 25gp | AT2: 1 | AU2: =VLOOKUP(AP2,AQ1:AT147,4,0) -> #REF! | AW2: 通用语
A3: 2 | B3: =IF(#REF!="","",#REF!) -> #REF! | C3: =IFERROR(VLOOKUP(B3,#REF!,5,FALSE),"") | D3: =IFERROR(VLOOKUP(B3,#REF!,4,FALSE),"") | E3: 2 | F3: =B3 -> #REF! | H3: =IF(#REF!<>"",#REF!,"") -> #REF! | I3: =IF(VLOOKUP(H3,#REF!,4,0)="√",1,0) -> #REF! | J3: =IF(VLOOKUP(H3,#REF!,5,0)="√",1,0) -> #REF! | L3: 牧师 | M3: =职业!$AI$4+#REF! -> #REF! | N3: =职业!$AI$4+#REF! -> #REF! | O3: =职业!$AI$4+#REF! -> #REF! | P3: =职业!$AI$4+#REF! -> #REF! | Q3: =职业!$AI$4+#REF! -> #REF! | R3: =职业!$AI$4+#REF! -> #REF! | S3: =职业!$AI$4+#REF! -> #REF! | T3: =职业!$AI$4+#REF! -> #REF! | ... AF3: =职业!$AI$4+#REF! -> #REF! | AK3: 2环 | AL3: 2 | AO3: =IF(ISBLANK(#REF!),,INDEX(AR1:AT149,MATCH(#REF!&"*",AQ1:AQ149,0),1)) -> #REF! | AP3: =IF(ISBLANK(#REF!),,INDEX(AQ1:AT149,MATCH(#REF!&"*",AQ1:AQ149,0),1)) -> #REF! | AQ3: 炽火胶_扁瓶 | AR3: 一种粘稠的流体，其一旦接触空气就会引起自燃。你可以用一个动作将这小瓶液体投到至多20尺远的地方，并利用冲击打破它。这个动作视为对一个生物或物件发动一次远程攻击，并将炽火胶视为一件临时武器。命中时，目标在它每回合开始时受到1d4点火焰伤害。被命中生物可以使用动作进行一次DC10的敏捷检定，以扑灭火焰来结束该伤害效应。 | AS3: 50gp | AT3: 1 | AU3: =VLOOKUP(AP3,AQ1:AT147,4,0) -> #REF! | AW3: 矮人语
A4: 3 | B4: =IF(#REF!="","",#REF!) -> #REF! | C4: =IFERROR(VLOOKUP(B4,#REF!,5,FALSE),"") | D4: =IFERROR(VLOOKUP(B4,#REF!,4,FALSE),"") | E4: 3 | F4: =B4 -> #REF! | H4: =IF(#REF!<>"",#REF!,"") -> #REF! | I4: =IF(VLOOKUP(H4,#REF!,4,0)="√",1,0) -> #REF! | J4: =IF(VLOOKUP(H4,#REF!,5,0)="√",1,0) -> #REF! | L4: 德鲁伊 | M4: =职业!$AI$5+#REF! -> #REF! | N4: =职业!$AI$5+#REF! -> #REF! | O4: =职业!$AI$5+#REF! -> #REF! | P4: =职业!$AI$5+#REF! -> #REF! | Q4: =职业!$AI$5+#REF! -> #REF! | R4: =职业!$AI$5+#REF! -> #REF! | S4: =职业!$AI$5+#REF! -> #REF! | T4: =职业!$AI$5+#REF! -> #REF! | ... AF4: =职业!$AI$5+#REF! -> #REF! | AK4: 3环 | AL4: 3 | AO4: =IF(ISBLANK(#REF!),,INDEX(AR1:AT149,MATCH(#REF!&"*",AQ1:AQ149,0),1)) -> #REF! | AP4: =IF(ISBLANK(#REF!),,INDEX(AQ1:AT149,MATCH(#REF!&"*",AQ1:AQ149,0),1)) -> #REF! | AQ4: 箭 | AR4: - | AS4: 1gp | AT4: 0.05 | AU4: =VLOOKUP(AP4,AQ1:AT147,4,0) -> #REF! | AW4: 精灵语
A5: 4 | B5: =IF(#REF!="","",#REF!) -> #REF! | C5: =IFERROR(VLOOKUP(B5,#REF!,5,FALSE),"") | D5: =IFERROR(VLOOKUP(B5,#REF!,4,FALSE),"") | E5: 4 | F5: =B5 -> #REF! | H5: =IF(#REF!<>"",#REF!,"") -> #REF! | I5: =IF(VLOOKUP(H5,#REF!,4,0)="√",1,0) -> #REF! | J5: =IF(VLOOKUP(H5,#REF!,5,0)="√",1,0) -> #REF! | L5: 圣武士 | M5: =ROUNDDOWN(职业!$AI$8/2,0)+#REF! -> #REF! | N5: =ROUNDDOWN(职业!$AI$8/2,0)+#REF! -> #REF! | O5: =ROUNDDOWN(职业!$AI$8/2,0)+#REF! -> #REF! | P5: =ROUNDDOWN(职业!$AI$8/2,0)+#REF! -> #REF! | Q5: =ROUNDDOWN(职业!$AI$8/2,0)+#REF! -> #REF! | R5: =ROUNDDOWN(职业!$AI$8/2,0)+#REF! -> #REF! | S5: =ROUNDDOWN(职业!$AI$8/2,0)+#REF! -> #REF! | T5: =ROUNDDOWN(职业!$AI$8/2,0)+#REF! -> #REF! | ... AF5: =ROUNDDOWN(职业!$AI$8/2,0)+#REF! -> #REF! | AI5: V 言语 | AK5: 4环 | AL5: 4 | AO5: =IF(ISBLANK(#REF!),,INDEX(AR1:AT149,MATCH(#REF!&"*",AQ1:AQ149,0),1)) -> #REF! | AP5: =IF(ISBLANK(#REF!),,INDEX(AQ1:AT149,MATCH(#REF!&"*",AQ1:AQ149,0),1)) -> #REF! | AQ5: 吹矢 | AR5: - | AS5: 1gp | AT5: 0.02 | AU5: =VLOOKUP(AP5,AQ1:AT147,4,0) -> #REF! | AW5: 巨人语
A6: 5 | B6: =IF(#REF!="","",#REF!) -> #REF! | C6: =IFERROR(VLOOKUP(B6,#REF!,5,FALSE),"") | D6: =IFERROR(VLOOKUP(B6,#REF!,4,FALSE),"") | E6: 5 | F6: =B6 -> #REF! | H6: =IF(#REF!<>"",#REF!,"") -> #REF! | I6: =IF(VLOOKUP(H6,#REF!,4,0)="√",1,0) -> #REF! | J6: =IF(VLOOKUP(H6,#REF!,5,0)="√",1,0) -> #REF! | L6: 游侠 | M6: 0 | N6: 2 | O6: 3 | P6: 3 | Q6: 4 | R6: 4 | S6: 5 | T6: 5 | U6: 6 | V6: 6 | W6: 7 | X6: 7 | Y6: 8 | Z6: 8 | AA6: 9 | AB6: 9 | AC6: 10 | AD6: 10 | AE6: 11 | AF6: 11 | AI6: S 姿势 | AK6: 5环 | AL6: 5 | AO6: =IF(ISBLANK(#REF!),,INDEX(AR1:AT149,MATCH(#REF!&"*",AQ1:AQ149,0),1)) -> #REF! | AP6: =IF(ISBLANK(#REF!),,INDEX(AQ1:AT149,MATCH(#REF!&"*",AQ1:AQ149,0),1)) -> #REF! | AQ6: 弩矢 | AR6: - | AS6: 1gp | AT6: 0.075 | AU6: =VLOOKUP(AP6,AQ1:AT147,4,0) -> #REF! | AW6: 侏儒语
A7: 6 | B7: =IF(#REF!="","",#REF!) -> #REF! | C7: =IFERROR(VLOOKUP(B7,#REF!,5,FALSE),"") | D7: =IFERROR(VLOOKUP(B7,#REF!,4,FALSE),"") | E7: 6 | F7: =B7 -> #REF! | H7: =IF(#REF!<>"",#REF!,"") -> #REF! | I7: =IF(VLOOKUP(H7,#REF!,4,0)="√",1,0) -> #REF! | J7: =IF(VLOOKUP(H7,#REF!,5,0)="√",1,0) -> #REF! | L7: 术士 | M7: 2 | N7: 3 | O7: 4 | P7: 5 | Q7: 6 | R7: 7 | S7: 8 | T7: 9 | U7: 10 | V7: 11 | W7: 12 | X7: 12 | Y7: 13 | Z7: 13 | AA7: 14 | AB7: 14 | AC7: 15 | AD7: 15 | AE7: 15 | AF7: 15 | AI7: M 材料 | AK7: 6环 | AL7: 6 | AO7: =IF(ISBLANK(#REF!),,INDEX(AR1:AT149,MATCH(#REF!&"*",AQ1:AQ149,0),1)) -> #REF! | AP7: =IF(ISBLANK(#REF!),,INDEX(AQ1:AT149,MATCH(#REF!&"*",AQ1:AQ149,0),1)) -> #REF! | AQ7: 投石索弹丸 | AR7: - | AS7: 0.04gp | AT7: 0.075 | AU7: =VLOOKUP(AP7,AQ1:AT147,4,0) -> #REF! | AW7: 地精语
A8: 7 | B8: =IF(#REF!="","",#REF!) -> #REF! | C8: =IFERROR(VLOOKUP(B8,#REF!,5,FALSE),"") | D8: =IFERROR(VLOOKUP(B8,#REF!,4,FALSE),"") | E8: 7 | F8: =B8 -> #REF! | H8: =IF(#REF!<>"",#REF!,"") -> #REF! | I8: =IF(VLOOKUP(H8,#REF!,4,0)="√",1,0) -> #REF! | J8: =IF(VLOOKUP(H8,#REF!,5,0)="√",1,0) -> #REF! | L8: 邪术师 | M8: 2 | N8: 3 | O8: 4 | P8: 5 | Q8: 6 | R8: 7 | S8: 8 | T8: 9 | U8: 10 | V8: 10 | W8: 11 | X8: 11 | Y8: 12 | Z8: 12 | AA8: 13 | AB8: 13 | AC8: 14 | AD8: 14 | AE8: 15 | AF8: 15 | AK8: 7环 | AL8: 7 | AO8: =IF(ISBLANK(#REF!),,INDEX(AR1:AT149,MATCH(#REF!&"*",AQ1:AQ149,0),1)) -> #REF! | AP8: =IF(ISBLANK(#REF!),,INDEX(AQ1:AT149,MATCH(#REF!&"*",AQ1:AQ149,0),1)) -> #REF! | AQ8: 子弹 | AR8: 采用复兴时期物品数据，如需使用现代弹药请自行填写。 | AS8: 3gp | AT8: 0.2 | AU8: =VLOOKUP(AP8,AQ1:AT147,4,0) -> #REF! | AW8: 半身人语
A9: 8 | B9: =IF(#REF!="","",#REF!) -> #REF! | C9: =IFERROR(VLOOKUP(B9,#REF!,5,FALSE),"") | D9: =IFERROR(VLOOKUP(B9,#REF!,4,FALSE),"") | E9: 8 | F9: =B9 -> #REF! | H9: =IF(#REF!<>"",#REF!,"") -> #REF! | I9: =IF(VLOOKUP(H9,#REF!,4,0)="√",1,0) -> #REF! | J9: =IF(VLOOKUP(H9,#REF!,5,0)="√",1,0) -> #REF! | L9: 法师 | M9: =职业!$AI$13+#REF! -> #REF! | N9: =职业!$AI$13+#REF! -> #REF! | O9: =职业!$AI$13+#REF! -> #REF! | P9: =职业!$AI$13+#REF! -> #REF! | Q9: =职业!$AI$13+#REF! -> #REF! | R9: =职业!$AI$13+#REF! -> #REF! | S9: =职业!$AI$13+#REF! -> #REF! | T9: =职业!$AI$13+#REF! -> #REF! | ... AF9: =职业!$AI$13+#REF! -> #REF! | AH9: 主职业 | AI9: 牧师 | AJ9: =#REF!+IF(#REF!="主职业",#REF!,IF(#REF!="兼职1",#REF!,IF(#REF!="兼职2",#REF!,))) -> #REF! | AK9: 8环 | AL9: 8 | AO9: =IF(ISBLANK(#REF!),,INDEX(AR1:AT149,MATCH(#REF!&"*",AQ1:AQ149,0),1)) -> #REF! | AP9: =IF(ISBLANK(#REF!),,INDEX(AQ1:AT149,MATCH(#REF!&"*",AQ1:AQ149,0),1)) -> #REF! | AQ9: 抗毒剂_小瓶 | AR9: 喝下瓶内液体的生物在1小时内进行对抗对毒素的豁免检定时具有优势。它无法为不死生物或构装生物提供任何增益。 | AS9: 50gp | AT9: 0 | AU9: =VLOOKUP(AP9,AQ1:AT147,4,0) -> #REF! | AW9: 兽人语
A10: 9 | B10: =IF(#REF!="","",#REF!) -> #REF! | C10: =IFERROR(VLOOKUP(B10,#REF!,5,FALSE),"") | D10: =IFERROR(VLOOKUP(B10,#REF!,4,FALSE),"") | E10: 9 | F10: =B10 -> #REF! | H10: =IF(#REF!<>"",#REF!,"") -> #REF! | I10: =IF(VLOOKUP(H10,#REF!,4,0)="√",1,0) -> #REF! | J10: =IF(VLOOKUP(H10,#REF!,5,0)="√",1,0) -> #REF! | AH10: 兼职1 | AI10: 圣武士 | AJ10: =#REF!+IF(#REF!="主职业",INT(#REF!/2),IF(#REF!="兼职1",INT(#REF!/2),IF(#REF!="兼职2",INT(#REF!/2),))) -> #REF! | AK10: 9环 | AL10: 9 | AO10: =IF(ISBLANK(#REF!),,INDEX(AR1:AT149,MATCH(#REF!&"*",AQ1:AQ149,0),1)) -> #REF! | AP10: =IF(ISBLANK(#REF!),,INDEX(AQ1:AT149,MATCH(#REF!&"*",AQ1:AQ149,0),1)) -> #REF! | AQ10: 水晶 | AR10: 奥术法器是一件用来引导奥术法术的特殊物品，它可以是一枚法球、一块水晶、一只权杖、一根特制法杖、一根魔杖般的长木条或是其它类似的物品。术士、邪术师或法师能将这样的物品用作施法法器。 | AS10: 10gp | AT10: 1 | AU10: =VLOOKUP(AP10,AQ1:AT147,4,0) -> #REF! | AW10: 深渊语
A11: 10 | B11: =IF(#REF!="","",#REF!) -> #REF! | C11: =IFERROR(VLOOKUP(B11,#REF!,5,FALSE),"") | D11: =IFERROR(VLOOKUP(B11,#REF!,4,FALSE),"") | E11: 10 | F11: =B11 -> #REF! | H11: =IF(#REF!<>"",#REF!,"") -> #REF! | I11: =IF(VLOOKUP(H11,#REF!,4,0)="√",1,0) -> #REF! | J11: =IF(VLOOKUP(H11,#REF!,5,0)="√",1,0) -> #REF! | L11: 主职业 | M11: =IF(#REF!="","",#REF!) -> #REF! | AH11: 兼职2 | AI11: 德鲁伊 | AJ11: =#REF!+IF(#REF!="主职业",#REF!,IF(#REF!="兼职1",#REF!,IF(#REF!="兼职2",#REF!,))) -> #REF! | AO11: =IF(ISBLANK(#REF!),,INDEX(AR1:AT149,MATCH(#REF!&"*",AQ1:AQ149,0),1)) -> #REF! | AP11: =IF(ISBLANK(#REF!),,INDEX(AQ1:AT149,MATCH(#REF!&"*",AQ1:AQ149,0),1)) -> #REF! | AQ11: 法球 | AR11: 奥术法器是一件用来引导奥术法术的特殊物品，它可以是一枚法球、一块水晶、一只权杖、一根特制法杖、一根魔杖般的长木条或是其它类似的物品。术士、邪术师或法师能将这样的物品用作施法法器。 | AS11: 20gp | AT11: 3 | AU11: =VLOOKUP(AP11,AQ1:AT147,4,0) -> #REF! | AW11: 天界语
A12: 11 | B12: =IF(#REF!="","",#REF!) -> #REF! | C12: =IFERROR(VLOOKUP(B12,#REF!,5,FALSE),"") | D12: =IFERROR(VLOOKUP(B12,#REF!,4,FALSE),"") | E12: 11 | F12: =B12 -> #REF! | H12: =IF(#REF!<>"",#REF!,"") -> #REF! | I12: =IF(VLOOKUP(H12,#REF!,4,0)="√",1,0) -> #REF! | J12: =IF(VLOOKUP(H12,#REF!,5,0)="√",1,0) -> #REF! | L12: 兼职1 | M12: =IF(#REF!="","",#REF!) -> #REF! | AI12: 法师 | AJ12: =#REF!+IF(#REF!="主职业",#REF!,IF(#REF!="兼职1",#REF!,IF(#REF!="兼职2",#REF!,))) -> #REF! | AQ12: 权杖 | AR12: 奥术法器是一件用来引导奥术法术的特殊物品，它可以是一枚法球、一块水晶、一只权杖、一根特制法杖、一根魔杖般的长木条或是其它类似的物品。术士、邪术师或法师能将这样的物品用作施法法器。 | AS12: 10gp | AT12: 2 | AW12: 龙语
A13: 12 | B13: =IF(#REF!="","",#REF!) -> #REF! | C13: =IFERROR(VLOOKUP(B13,#REF!,5,FALSE),"") | D13: =IFERROR(VLOOKUP(B13,#REF!,4,FALSE),"") | E13: 12 | F13: =B13 -> #REF! | H13: =IF(#REF!<>"",#REF!,"") -> #REF! | I13: =IF(VLOOKUP(H13,#REF!,4,0)="√",1,0) -> #REF! | J13: =IF(VLOOKUP(H13,#REF!,5,0)="√",1,0) -> #REF! | L13: 兼职2 | M13: =IF(#REF!="","",#REF!) -> #REF! | AI13: 奇械师 | AJ13: =#REF!+IF(#REF!="主职业",INT(#REF!/2),IF(#REF!="兼职1",INT(#REF!/2),IF(#REF!="兼职2",INT(#REF!/2),))) -> #REF! | AO13: =IF(ISBLANK(#REF!),,INDEX(AR1:AT149,MATCH(#REF!&"*",AQ1:AQ149,0),1)) -> #REF! | AP13: =IF(ISBLANK(#REF!),,INDEX(AQ1:AT149,MATCH(#REF!&"*",AQ1:AQ149,0),1)) -> #REF! | AQ13: 法杖 | AR13: 奥术法器是一件用来引导奥术法术的特殊物品，它可以是一枚法球、一块水晶、一只权杖、一根特制法杖、一根魔杖般的长木条或是其它类似的物品。术士、邪术师或法师能将这样的物品用作施法法器。 | AS13: 5gp | AT13: 4 | AU13: =VLOOKUP(AP13,AQ1:AT147,4,0) -> #REF! | AW13: 深潜语
A14: 13 | B14: =IF(#REF!="","",#REF!) -> #REF! | C14: =IFERROR(VLOOKUP(B14,#REF!,5,FALSE),"") | D14: =IFERROR(VLOOKUP(B14,#REF!,4,FALSE),"") | E14: 13 | F14: =B14 -> #REF! | H14: =IF(#REF!<>"",#REF!,"") -> #REF! | I14: =IF(VLOOKUP(H14,#REF!,4,0)="√",1,0) -> #REF! | J14: =IF(VLOOKUP(H14,#REF!,5,0)="√",1,0) -> #REF! | L14: =IFERROR(IF(#REF!="主职业",VLOOKUP(M11,L1:AF9,#REF!+1,IF(#REF!="兼职1",VLOOKUP(M12,L1:AF9,#REF!+1,IF(#REF!="兼职2",VLOOKUP(M13,L1:AF9,#REF!+1,0)))))),"") | AL14: 体型 | AO14: =IF(ISBLANK(#REF!),,INDEX(AR1:AT149,MATCH(#REF!&"*",AQ1:AQ149,0),1)) -> #REF! | AP14: =IF(ISBLANK(#REF!),,INDEX(AQ1:AT149,MATCH(#REF!&"*",AQ1:AQ149,0),1)) -> #REF! | AQ14: 魔杖 | AR14: 奥术法器是一件用来引导奥术法术的特殊物品，它可以是一枚法球、一块水晶、一只权杖、一根特制法杖、一根魔杖般的长木条或是其它类似的物品。术士、邪术师或法师能将这样的物品用作施法法器。 | AS14: 10gp | AT14: 1 | AU14: =VLOOKUP(AP14,AQ1:AT147,4,0) -> #REF! | AW14: 炼狱语
A15: 14 | B15: =IF(#REF!="","",#REF!) -> #REF! | C15: =IFERROR(VLOOKUP(B15,#REF!,5,FALSE),"") | D15: =IFERROR(VLOOKUP(B15,#REF!,4,FALSE),"") | E15: 14 | F15: =B15 -> #REF! | H15: =IF(#REF!<>"",#REF!,"") -> #REF! | I15: =IF(VLOOKUP(H15,#REF!,4,0)="√",1,0) -> #REF! | J15: =IF(VLOOKUP(H15,#REF!,5,0)="√",1,0) -> #REF! | AL15: 微型 | AO15: =IF(ISBLANK(#REF!),,INDEX(AR1:AT149,MATCH(#REF!&"*",AQ1:AQ149,0),1)) -> #REF! | AP15: =IF(ISBLANK(#REF!),,INDEX(AQ1:AT149,MATCH(#REF!&"*",AQ1:AQ149,0),1)) -> #REF! | AQ15: 背包 | AR15: 一个背包可以容纳1立方尺或30磅重的装备，你还可以将物品系在背包外面，例如一卷铺盖或是一捆绳索。 | AS15: 2gp | AT15: 5 | AU15: =VLOOKUP(AP15,AQ1:AT147,4,0) -> #REF! | AW15: 原初语
A16: 15 | B16: =IF(#REF!="","",#REF!) -> #REF! | C16: =IFERROR(VLOOKUP(B16,#REF!,5,FALSE),"") | D16: =IFERROR(VLOOKUP(B16,#REF!,4,FALSE),"") | E16: 15 | F16: =B16 -> #REF! | H16: =IF(#REF!<>"",#REF!,"") -> #REF! | I16: =IF(VLOOKUP(H16,#REF!,4,0)="√",1,0) -> #REF! | J16: =IF(VLOOKUP(H16,#REF!,5,0)="√",1,0) -> #REF! | AL16: 小型 | AO16: =IF(ISBLANK(#REF!),,INDEX(AR1:AT149,MATCH(#REF!&"*",AQ1:AQ149,0),1)) -> #REF! | AP16: =IF(ISBLANK(#REF!),,INDEX(AQ1:AT149,MATCH(#REF!&"*",AQ1:AQ149,0),1)) -> #REF! | AQ16: 滚珠_一包1000粒 | AR16: 你可以用一个动作将这些小金属珠从袋子中洒出，并覆盖一片边长10尺的方形区域。穿过这片区域的生物必须进行一次DC10的敏捷豁免，豁免失败则摔至倒地。以半速穿过该区域的生物不需要进行该豁免。 | AS16: 1gp | AT16: 2 | AU16: =VLOOKUP(AP16,AQ1:AT147,4,0) -> #REF! | AW16: 木族语
A17: 16 | B17: =IF(#REF!="","",#REF!) -> #REF! | C17: =IFERROR(VLOOKUP(B17,#REF!,5,FALSE),"") | D17: =IFERROR(VLOOKUP(B17,#REF!,4,FALSE),"") | E17: 16 | F17: =B17 -> #REF! | H17: =IF(#REF!<>"",#REF!,"") -> #REF! | I17: =IF(VLOOKUP(H17,#REF!,4,0)="√",1,0) -> #REF! | J17: =IF(VLOOKUP(H17,#REF!,5,0)="√",1,0) -> #REF! | AL17: 中型 | AO17: =IF(ISBLANK(#REF!),,INDEX(AR1:AT149,MATCH(#REF!&"*",AQ1:AQ149,0),1)) -> #REF! | AP17: =IF(ISBLANK(#REF!),,INDEX(AQ1:AT149,MATCH(#REF!&"*",AQ1:AQ149,0),1)) -> #REF! | AQ17: 粗腰桶 | AR17: 一个粗腰桶可以容纳40加仑的液体或4立方尺的固体。 | AS17: 2gp | AT17: 70 | AU17: =VLOOKUP(AP17,AQ1:AT147,4,0) -> #REF! | AW17: 地底通用语
A18: 17 | B18: =IF(#REF!="","",#REF!) -> #REF! | C18: =IFERROR(VLOOKUP(B18,#REF!,5,FALSE),"") | D18: =IFERROR(VLOOKUP(B18,#REF!,4,FALSE),"") | E18: 17 | F18: =B18 -> #REF! | H18: =IF(#REF!<>"",#REF!,"") -> #REF! | I18: =IF(VLOOKUP(H18,#REF!,4,0)="√",1,0) -> #REF! | J18: =IF(VLOOKUP(H18,#REF!,5,0)="√",1,0) -> #REF! | M18: 戏法 | N18: 变化 | O18: 动作 | P18: 触及 | Q18: 立即 | V18: 背包1 | W18: 背包2 | X18: 次元袋1 | Y18: 次元袋2 | AI18: 经验值 | AL18: 大型 | AO18: =IF(ISBLANK(#REF!),,INDEX(AR1:AT149,MATCH(#REF!&"*",AQ1:AQ149,0),1)) -> #REF! | AP18: =IF(ISBLANK(#REF!),,INDEX(AQ1:AT149,MATCH(#REF!&"*",AQ1:AQ149,0),1)) -> #REF! | AQ18: 篮子 | AR18: 篮子可以容纳2立方尺或40磅重的物品。 | AS18: 0.4gp | AT18: 2 | AU18: =VLOOKUP(AP18,AQ1:AT147,4,0) -> #REF! | AW18: 水族语
A19: 18 | B19: =IF(#REF!="","",#REF!) -> #REF! | C19: =IFERROR(VLOOKUP(B19,#REF!,5,FALSE),"") | D19: =IFERROR(VLOOKUP(B19,#REF!,4,FALSE),"") | E19: 18 | F19: =B19 -> #REF! | H19: =IF(#REF!<>"",#REF!,"") -> #REF! | I19: =IF(VLOOKUP(H19,#REF!,4,0)="√",1,0) -> #REF! | J19: =IF(VLOOKUP(H19,#REF!,5,0)="√",1,0) -> #REF! | M19: 1 | N19: 塑能 | O19: 附赠动作 | P19: 自身 | Q19: 1轮 | V19: =SUM(#REF!*#REF!) -> #REF! | W19: =SUM(#REF!*#REF!) -> #REF! | X19: =SUM(#REF!*#REF!) -> #REF! | Y19: =SUM(#REF!*#REF!) -> #REF! | AI19: Exp | AJ19: Lv | AL19: 巨型 | AO19: =IF(ISBLANK(#REF!),,INDEX(AR1:AT149,MATCH(#REF!&"*",AQ1:AQ149,0),1)) -> #REF! | AP19: =IF(ISBLANK(#REF!),,INDEX(AQ1:AT149,MATCH(#REF!&"*",AQ1:AQ149,0),1)) -> #REF! | AQ19: 铺盖 | AR19: - | AS19: 1gp | AT19: 7 | AU19: =VLOOKUP(AP19,AQ1:AT147,4,0) -> #REF! | AW19: 气族语
A20: 19 | B20: =IF(#REF!="","",#REF!) -> #REF! | C20: =IFERROR(VLOOKUP(B20,#REF!,5,FALSE),"") | D20: =IFERROR(VLOOKUP(B20,#REF!,4,FALSE),"") | E20: 19 | F20: =B20 -> #REF! | H20: =IF(#REF!<>"",#REF!,"") -> #REF! | I20: =IF(VLOOKUP(H20,#REF!,4,0)="√",1,0) -> #REF! | J20: =IF(VLOOKUP(H20,#REF!,5,0)="√",1,0) -> #REF! | M20: 2 | N20: 防护 | O20: 1分钟 | P20: 15尺 | Q20: 1分钟 | V20: =SUM(#REF!*#REF!) -> #REF! | W20: =SUM(#REF!*#REF!) -> #REF! | X20: =SUM(#REF!*#REF!) -> #REF! | Y20: =SUM(#REF!*#REF!) -> #REF! | AI20: 0 | AJ20: 1 | AL20: 超巨型 | AO20: =IF(ISBLANK(#REF!),,INDEX(AR1:AT149,MATCH(#REF!&"*",AQ1:AQ149,0),1)) -> #REF! | AP20: =IF(ISBLANK(#REF!),,INDEX(AQ1:AT149,MATCH(#REF!&"*",AQ1:AQ149,0),1)) -> #REF! | AQ20: 铃铛 | AR20: - | AS20: 1gp | AT20: 0 | AU20: =VLOOKUP(AP20,AQ1:AT147,4,0) -> #REF! | AW20: 刻洛语
A21: 20 | B21: =IF(#REF!="","",#REF!) -> #REF! | C21: =IFERROR(VLOOKUP(B21,#REF!,5,FALSE),"") | D21: =IFERROR(VLOOKUP(B21,#REF!,4,FALSE),"") | E21: 20 | F21: =B21 -> #REF! | H21: =IF(#REF!<>"",#REF!,"") -> #REF! | I21: =IF(VLOOKUP(H21,#REF!,4,0)="√",1,0) -> #REF! | J21: =IF(VLOOKUP(H21,#REF!,5,0)="√",1,0) -> #REF! | M21: 3 | N21: 死灵 | O21: 动作或仪式 | P21: 30尺 | Q21: 10分钟 | V21: =SUM(#REF!*#REF!) -> #REF! | W21: =SUM(#REF!*#REF!) -> #REF! | X21: =SUM(#REF!*#REF!) -> #REF! | Y21: =SUM(#REF!*#REF!) -> #REF! | AI21: 300 | AJ21: 2 | AO21: =IF(ISBLANK(#REF!),,INDEX(AR1:AT149,MATCH(#REF!&"*",AQ1:AQ149,0),1)) -> #REF! | AP21: =IF(ISBLANK(#REF!),,INDEX(AQ1:AT149,MATCH(#REF!&"*",AQ1:AQ149,0),1)) -> #REF! | AQ21: 毯子 | AR21: - | AS21: 0.5gp | AT21: 3 | AU21: =VLOOKUP(AP21,AQ1:AT147,4,0) -> #REF! | AW21: 人鱼语
A22: 21 | B22: =IF(#REF!="","",#REF!) -> #REF! | C22: =IFERROR(VLOOKUP(B22,#REF!,5,FALSE),"") | D22: =IFERROR(VLOOKUP(B22,#REF!,4,FALSE),"") | E22: 21 | F22: =B22 -> #REF! | H22: =IF(#REF!<>"",#REF!,"") -> #REF! | I22: =IF(VLOOKUP(H22,#REF!,4,0)="√",1,0) -> #REF! | J22: =IF(VLOOKUP(H22,#REF!,5,0)="√",1,0) -> #REF! | M22: 4 | N22: 预言 | O22: 1分钟或仪式 | P22: 60尺 | Q22: 1小时 | V22: =SUM(#REF!*#REF!) -> #REF! | W22: =SUM(#REF!*#REF!) -> #REF! | X22: =SUM(#REF!*#REF!) -> #REF! | Y22: =SUM(#REF!*#REF!) -> #REF! | AI22: 900 | AJ22: 3 | AL22: 装备同调数量 | AO22: =IF(ISBLANK(#REF!),,INDEX(AR1:AT149,MATCH(#REF!&"*",AQ1:AQ149,0),1)) -> #REF! | AP22: =IF(ISBLANK(#REF!),,INDEX(AQ1:AT149,MATCH(#REF!&"*",AQ1:AQ149,0),1)) -> #REF! | AQ22: 滑轮组 | AR22: 一组滑轮组，其中配有一根绳索绕过轮组中，其上还装着一个系物的钩子。滑轮组可以让你提起相当于你正常举重四倍重量的物件。 | AS22: 5gp | AT22: 5 | AU22: =VLOOKUP(AP22,AQ1:AT147,4,0) -> #REF! | AW22: 牛头人语
A23: 22 | B23: =IF(#REF!="","",#REF!) -> #REF! | C23: =IFERROR(VLOOKUP(B23,#REF!,5,FALSE),"") | D23: =IFERROR(VLOOKUP(B23,#REF!,4,FALSE),"") | E23: 22 | F23: =B23 -> #REF! | H23: =IF(#REF!<>"",#REF!,"") -> #REF! | I23: =IF(VLOOKUP(H23,#REF!,4,0)="√",1,0) -> #REF! | J23: =IF(VLOOKUP(H23,#REF!,5,0)="√",1,0) -> #REF! | M23: 5 | N23: 咒法 | O23: 10分钟 | P23: 90尺 | Q23: 8小时 | V23: =SUM(#REF!*#REF!) -> #REF! | W23: =SUM(#REF!*#REF!) -> #REF! | X23: =SUM(#REF!*#REF!) -> #REF! | Y23: =SUM(#REF!*#REF!) -> #REF! | AI23: =AI22*AJ22 -> 2700 | AJ23: 4 | AL23: =IF(#REF!="O",1,0) -> #REF! | AQ23: 书 | AR23: 一本书可能写着诗歌、故事或是其他的内容。里面可能有关于某个特定地区的学识信息，也可能有侏儒语记载的机械图和笔记，或者任何其它能够用文字或图形表达的内容。一本载有法术的书则是一本法术书（见后文详述）。 | AS23: 28gp | AT23: 5 | AW23: 斯芬克斯语
A24: 23 | B24: =IF(#REF!="","",#REF!) -> #REF! | C24: =IFERROR(VLOOKUP(B24,#REF!,5,FALSE),"") | D24: =IFERROR(VLOOKUP(B24,#REF!,4,FALSE),"") | E24: 23 | F24: =B24 -> #REF! | H24: =IF(#REF!<>"",#REF!,"") -> #REF! | I24: =IF(VLOOKUP(H24,#REF!,4,0)="√",1,0) -> #REF! | J24: =IF(VLOOKUP(H24,#REF!,5,0)="√",1,0) -> #REF! | M24: 6 | N24: 附魔 | O24: 1小时 | P24: 120尺 | Q24: 24小时 | V24: =SUM(#REF!*#REF!) -> #REF! | W24: =SUM(#REF!*#REF!) -> #REF! | X24: =SUM(#REF!*#REF!) -> #REF! | Y24: =SUM(#REF!*#REF!) -> #REF! | AI24: 6500 | AJ24: 5 | AL24: =IF(#REF!="O",1,0) -> #REF! | AQ24: 玻璃瓶 | AR24: - | AS24: 2gp | AT24: 2 | AW24: 吉斯语
A25: 24 | B25: =IF(#REF!="","",#REF!) -> #REF! | C25: =IFERROR(VLOOKUP(B25,#REF!,5,FALSE),"") | D25: =IFERROR(VLOOKUP(B25,#REF!,4,FALSE),"") | E25: 24 | F25: =B25 -> #REF! | H25: =IF(#REF!<>"",#REF!,"") -> #REF! | I25: =IF(VLOOKUP(H25,#REF!,4,0)="√",1,0) -> #REF! | J25: =IF(VLOOKUP(H25,#REF!,5,0)="√",1,0) -> #REF! | M25: 7 | N25: 幻术 | O25: 8小时 | P25: 150尺 | Q25: 专注，至多1轮 | V25: =SUM(#REF!*#REF!) -> #REF! | W25: =SUM(#REF!*#REF!) -> #REF! | X25: =SUM(#REF!*#REF!) -> #REF! | Y25: =SUM(#REF!*#REF!) -> #REF! | AI25: 14000 | AJ25: 6 | AL25: =IF(#REF!="O",1,0) -> #REF! | AQ25: 水桶 | AR25: 水桶可以容纳3加仑的液体或½立方尺的固体。 | AS25: 0.05gp | AT25: 2 | AW25: 象族语
A26: 25 | B26: =IF(#REF!="","",#REF!) -> #REF! | C26: =IFERROR(VLOOKUP(B26,#REF!,5,FALSE),"") | D26: =IFERROR(VLOOKUP(B26,#REF!,4,FALSE),"") | E26: 25 | F26: =B26 -> #REF! | H26: =IF(#REF!<>"",#REF!,"") -> #REF! | I26: =IF(VLOOKUP(H26,#REF!,4,0)="√",1,0) -> #REF! | J26: =IF(VLOOKUP(H26,#REF!,5,0)="√",1,0) -> #REF! | M26: 8 | P26: 300尺 | Q26: 专注，至多1分钟 | V26: =SUM(#REF!*#REF!) -> #REF! | W26: =SUM(#REF!*#REF!) -> #REF! | X26: =SUM(#REF!*#REF!) -> #REF! | Y26: =SUM(#REF!*#REF!) -> #REF! | AI26: 23000 | AJ26: 7 | AL26: =IF(#REF!="O",1,0) -> #REF! | AQ26: 铁蒺藜_一包20枚 | AR26: 你可以用一个动作将一包铁蒺藜撒出，并覆盖一块边长5尺的方形区域。任何进入该区域的生物必须进行一次DC15的敏捷豁免，豁免失败则该生物停止移动，并受到1点穿刺伤害。在该生物恢复至少1点生命值前，其步行速度将减少10尺。以半速穿过该区域的生物不需要进行该豁免。 | AS26: 1gp | AT26: 2 | AW26: 维多肯语
A27: 26 | B27: =IF(#REF!="","",#REF!) -> #REF! | C27: =IFERROR(VLOOKUP(B27,#REF!,5,FALSE),"") | D27: =IFERROR(VLOOKUP(B27,#REF!,4,FALSE),"") | E27: 26 | F27: =B27 -> #REF! | H27: =IF(#REF!<>"",#REF!,"") -> #REF! | I27: =IF(VLOOKUP(H27,#REF!,4,0)="√",1,0) -> #REF! | J27: =IF(VLOOKUP(H27,#REF!,5,0)="√",1,0) -> #REF! | M27: 9 | P27: 自身(5尺半径) | Q27: 专注，至多10分钟 | V27: =SUM(#REF!*#REF!) -> #REF! | W27: =SUM(#REF!*#REF!) -> #REF! | X27: =SUM(#REF!*#REF!) -> #REF! | Y27: =SUM(#REF!*#REF!) -> #REF! | AI27: 34000 | AJ27: 8 | AL27: =IF(#REF!="O",1,0) -> #REF! | AQ27: 蜡烛 | AR27: 一只蜡烛可以为其身边5尺半径范围提供明亮光照，以及该范围外5尺的微光光照。蜡烛的照明效果可以持续1小时。 | AS27: 0.01gp | AT27: 0 | AW27: 梦族语
A28: 27 | B28: =IF(#REF!="","",#REF!) -> #REF! | C28: =IFERROR(VLOOKUP(B28,#REF!,5,FALSE),"") | D28: =IFERROR(VLOOKUP(B28,#REF!,4,FALSE),"") | E28: 27 | F28: =B28 -> #REF! | H28: =IF(#REF!<>"",#REF!,"") -> #REF! | I28: =IF(VLOOKUP(H28,#REF!,4,0)="√",1,0) -> #REF! | J28: =IF(VLOOKUP(H28,#REF!,5,0)="√",1,0) -> #REF! | P28: 自身(30尺半径) | Q28: 专注，至多1小时 | V28: =SUM(#REF!*#REF!) -> #REF! | W28: =SUM(#REF!*#REF!) -> #REF! | X28: =SUM(#REF!*#REF!) -> #REF! | Y28: =SUM(#REF!*#REF!) -> #REF! | AI28: 48000 | AJ28: 9 | AL28: =IF(#REF!="O",1,0) -> #REF! | AQ28: 弩矢匣 | AR28: 一只木匣能装二十支弩矢。 | AS28: 1gp | AT28: 1 | AW28: 狮族语
A29: 28 | B29: =IF(#REF!="","",#REF!) -> #REF! | C29: =IFERROR(VLOOKUP(B29,#REF!,5,FALSE),"") | D29: =IFERROR(VLOOKUP(B29,#REF!,4,FALSE),"") | E29: 28 | F29: =B29 -> #REF! | H29: =IF(#REF!<>"",#REF!,"") -> #REF! | I29: =IF(VLOOKUP(H29,#REF!,4,0)="√",1,0) -> #REF! | J29: =IF(VLOOKUP(H29,#REF!,5,0)="√",1,0) -> #REF! | P29: 自身(15尺立方) | Q29: 10日 | AI29: 64000 | AJ29: 10 | AL29: =IF(#REF!="O",1,0) -> #REF! | AQ29: 地图或卷轴匣 | AR29: 一个圆柱形皮匣能够装上十张卷起的纸或是五张卷起的羊皮纸。 | AS29: 1gp | AT29: 1 | AW29: 阿兰寇拉语
A30: 29 | B30: =IF(#REF!="","",#REF!) -> #REF! | C30: =IFERROR(VLOOKUP(B30,#REF!,5,FALSE),"") | D30: =IFERROR(VLOOKUP(B30,#REF!,4,FALSE),"") | E30: 29 | F30: =B30 -> #REF! | H30: =IF(#REF!<>"",#REF!,"") -> #REF! | I30: =IF(VLOOKUP(H30,#REF!,4,0)="√",1,0) -> #REF! | J30: =IF(VLOOKUP(H30,#REF!,5,0)="√",1,0) -> #REF! | P30: 自身(30尺锥状) | Q30: 7日 | V30: =SUM(#REF!*#REF!) -> #REF! | W30: =SUM(#REF!*#REF!) -> #REF! | X30: =SUM(#REF!*#REF!) -> #REF! | Y30: =SUM(#REF!*#REF!) -> #REF! | AI30: 85000 | AJ30: 11 | AL30: =IF(#REF!="O",1,0) -> #REF! | AQ30: 链条_10尺 | AR30: 一根链条有10点生命值。它可以被一次成功的DC20力量检定挣断。 | AS30: 5gp | AT30: 10 | AW30: 哈多兹鼯猴人语
A31: 30 | B31: =IF(#REF!="","",#REF!) -> #REF! | C31: =IFERROR(VLOOKUP(B31,#REF!,5,FALSE),"") | D31: =IFERROR(VLOOKUP(B31,#REF!,4,FALSE),"") | E31: 30 | F31: =B31 -> #REF! | H31: =IF(#REF!<>"",#REF!,"") -> #REF! | I31: =IF(VLOOKUP(H31,#REF!,4,0)="√",1,0) -> #REF! | J31: =IF(VLOOKUP(H31,#REF!,5,0)="√",1,0) -> #REF! | P31: 自身(30尺线状) | Q31: 30日 | V31: =SUM(#REF!*#REF!) -> #REF! | W31: =SUM(#REF!*#REF!) -> #REF! | X31: =SUM(#REF!*#REF!) -> #REF! | Y31: =SUM(#REF!*#REF!) -> #REF! | AI31: 100000 | AJ31: 12 | AL31: =IF(#REF!="O",1,0) -> #REF! | AQ31: 粉笔_1块 | AR31: - | AS31: 0.01gp | AT31: 0 | AW31: 斯里克林语
A32: 31 | B32: =IF(#REF!="","",#REF!) -> #REF! | C32: =IFERROR(VLOOKUP(B32,#REF!,5,FALSE),"") | D32: =IFERROR(VLOOKUP(B32,#REF!,4,FALSE),"") | E32: 31 | F32: =B32 -> #REF! | H32: =IF(#REF!<>"",#REF!,"") -> #REF! | I32: =IF(VLOOKUP(H32,#REF!,4,0)="√",1,0) -> #REF! | J32: =IF(VLOOKUP(H32,#REF!,5,0)="√",1,0) -> #REF! | P32: 1里 | Q32: 特殊 | V32: =SUM(#REF!*#REF!) -> #REF! | W32: =SUM(#REF!*#REF!) -> #REF! | X32: =SUM(#REF!*#REF!) -> #REF! | Y32: =SUM(#REF!*#REF!) -> #REF! | AI32: 120000 | AJ32: 13 | AL32: =IF(#REF!="O",1,0) -> #REF! | AQ32: 箱子 | AR32: 一个箱子可以容纳12立方尺或300磅重的物品。 | AS32: 5gp | AT32: 25
A33: 32 | B33: =IF(#REF!="","",#REF!) -> #REF! | C33: =IFERROR(VLOOKUP(B33,#REF!,5,FALSE),"") | D33: =IFERROR(VLOOKUP(B33,#REF!,4,FALSE),"") | E33: 32 | F33: =B33 -> #REF! | H33: =IF(#REF!<>"",#REF!,"") -> #REF! | I33: =IF(VLOOKUP(H33,#REF!,4,0)="√",1,0) -> #REF! | J33: =IF(VLOOKUP(H33,#REF!,5,0)="√",1,0) -> #REF! | P33: 视野内 | Q33: 直到被解除 | V33: =SUM(#REF!*#REF!) -> #REF! | W33: =SUM(#REF!*#REF!) -> #REF! | X33: =SUM(#REF!*#REF!) -> #REF! | Y33: =SUM(#REF!*#REF!) -> #REF! | AI33: 140000 | AJ33: 14 | AL33: =IF(#REF!="O",1,0) -> #REF! | AQ33: 攀爬工具 | AR33: 一套攀爬工具包括特制的岩钉，靴子包头，手套和系带。你可以用一个动作来运用攀爬工具锚定自己；此时你不会从锚定处摔落超过25尺，且在解除锚定前无法从锚定处向外攀爬超过25尺。 | AS33: 25gp | AT33: 12
A34: 33 | B34: =IF(#REF!="","",#REF!) -> #REF! | C34: =IFERROR(VLOOKUP(B34,#REF!,5,FALSE),"") | D34: =IFERROR(VLOOKUP(B34,#REF!,4,FALSE),"") | E34: 33 | F34: =B34 -> #REF! | H34: =IF(#REF!<>"",#REF!,"") -> #REF! | I34: =IF(VLOOKUP(H34,#REF!,4,0)="√",1,0) -> #REF! | J34: =IF(VLOOKUP(H34,#REF!,5,0)="√",1,0) -> #REF! | P34: 特殊 | Q34: 直至被解除或被触发 | V34: =SUM(#REF!*#REF!) -> #REF! | W34: =SUM(#REF!*#REF!) -> #REF! | X34: =SUM(#REF!*#REF!) -> #REF! | Y34: =SUM(#REF!*#REF!) -> #REF! | AI34: 165000 | AJ34: 15 | AL34: =IF(#REF!="O",1,0) -> #REF! | AQ34: 普通服装 | AR34: - | AS34: 0.5gp | AT34: 3
A35: 34 | B35: =IF(#REF!="","",#REF!) -> #REF! | C35: =IFERROR(VLOOKUP(B35,#REF!,5,FALSE),"") | D35: =IFERROR(VLOOKUP(B35,#REF!,4,FALSE),"") | E35: 34 | F35: =B35 -> #REF! | H35: =IF(#REF!<>"",#REF!,"") -> #REF! | I35: =IF(VLOOKUP(H35,#REF!,4,0)="√",1,0) -> #REF! | J35: =IF(VLOOKUP(H35,#REF!,5,0)="√",1,0) -> #REF! | Q35: 直至被驱散 | V35: =SUM(#REF!*#REF!) -> #REF! | W35: =SUM(#REF!*#REF!) -> #REF! | X35: =SUM(#REF!*#REF!) -> #REF! | Y35: =SUM(#REF!*#REF!) -> #REF! | AI35: 195000 | AJ35: 16 | AL35: =IF(#REF!="O",1,0) -> #REF! | AQ35: 表演服装 | AR35: - | AS35: 5gp | AT35: 4
A36: 35 | B36: =IF(#REF!="","",#REF!) -> #REF! | C36: =IFERROR(VLOOKUP(B36,#REF!,5,FALSE),"") | D36: =IFERROR(VLOOKUP(B36,#REF!,4,FALSE),"") | E36: 35 | F36: =B36 -> #REF! | H36: =IF(#REF!<>"",#REF!,"") -> #REF! | I36: =IF(VLOOKUP(H36,#REF!,4,0)="√",1,0) -> #REF! | J36: =IF(VLOOKUP(H36,#REF!,5,0)="√",1,0) -> #REF! | V36: =SUM(#REF!*#REF!) -> #REF! | W36: =SUM(#REF!*#REF!) -> #REF! | X36: =SUM(#REF!*#REF!) -> #REF! | Y36: =SUM(#REF!*#REF!) -> #REF! | AI36: 225000 | AJ36: 17 | AL36: =IF(#REF!="O",1,0) -> #REF! | AQ36: 高档服装 | AR36: - | AS36: 15gp | AT36: 6
A37: 36 | B37: =IF(#REF!="","",#REF!) -> #REF! | C37: =IFERROR(VLOOKUP(B37,#REF!,5,FALSE),"") | D37: =IFERROR(VLOOKUP(B37,#REF!,4,FALSE),"") | E37: 36 | F37: =B37 -> #REF! | H37: =IF(#REF!<>"",#REF!,"") -> #REF! | I37: =IF(VLOOKUP(H37,#REF!,4,0)="√",1,0) -> #REF! | J37: =IF(VLOOKUP(H37,#REF!,5,0)="√",1,0) -> #REF! | V37: =SUM(#REF!*#REF!) -> #REF! | W37: =SUM(#REF!*#REF!) -> #REF! | X37: =SUM(#REF!*#REF!) -> #REF! | Y37: =SUM(#REF!*#REF!) -> #REF! | AI37: 265000 | AJ37: 18 | AL37: =IF(#REF!="O",1,0) -> #REF! | AQ37: 旅行者服装 | AR37: - | AS37: 2gp | AT37: 4
A38: 37 | B38: =IF(#REF!="","",#REF!) -> #REF! | C38: =IFERROR(VLOOKUP(B38,#REF!,5,FALSE),"") | D38: =IFERROR(VLOOKUP(B38,#REF!,4,FALSE),"") | E38: 37 | F38: =B38 -> #REF! | H38: =IF(#REF!<>"",#REF!,"") -> #REF! | I38: =IF(VLOOKUP(H38,#REF!,4,0)="√",1,0) -> #REF! | J38: =IF(VLOOKUP(H38,#REF!,5,0)="√",1,0) -> #REF! | V38: =SUM(#REF!*#REF!) -> #REF! | W38: =SUM(#REF!*#REF!) -> #REF! | X38: =SUM(#REF!*#REF!) -> #REF! | Y38: =SUM(#REF!*#REF!) -> #REF! | AI38: 305000 | AJ38: 19 | AL38: =IF(#REF!="O",1,0) -> #REF! | AQ38: 材料包 | AR38: 材料包是一个防水的皮质小小包，其内有间格用以放置各种材料成分以及其它你需要用以施展法术的特殊物品。某些有着特定价格的材料不包含在材料包中（详见相关法术的描述内容）。 | AS38: 25gp | AT38: 2
A39: 38 | B39: =IF(#REF!="","",#REF!) -> #REF! | C39: =IFERROR(VLOOKUP(B39,#REF!,5,FALSE),"") | D39: =IFERROR(VLOOKUP(B39,#REF!,4,FALSE),"") | E39: 38 | F39: =B39 -> #REF! | H39: =IF(#REF!<>"",#REF!,"") -> #REF! | I39: =IF(VLOOKUP(H39,#REF!,4,0)="√",1,0) -> #REF! | J39: =IF(VLOOKUP(H39,#REF!,5,0)="√",1,0) -> #REF! | V39: =SUM(#REF!*#REF!) -> #REF! | W39: =SUM(#REF!*#REF!) -> #REF! | X39: =SUM(#REF!*#REF!) -> #REF! | Y39: =SUM(#REF!*#REF!) -> #REF! | AI39: 355000 | AJ39: 20 | AQ39: 撬棍 | AR39: 在适当的地方使用撬棍时，可以让相应的力量检定具有优势。 | AS39: 2gp | AT39: 5
A40: 39 | B40: =IF(#REF!="","",#REF!) -> #REF! | C40: =IFERROR(VLOOKUP(B40,#REF!,5,FALSE),"") | D40: =IFERROR(VLOOKUP(B40,#REF!,4,FALSE),"") | E40: 39 | F40: =B40 -> #REF! | H40: =IF(#REF!<>"",#REF!,"") -> #REF! | I40: =IF(VLOOKUP(H40,#REF!,4,0)="√",1,0) -> #REF! | J40: =IF(VLOOKUP(H40,#REF!,5,0)="√",1,0) -> #REF! | AQ40: 槲寄生枝条 | AR40: 德鲁伊法器是一件用来引导德鲁伊法术的特殊物品。它可以是一枝槲寄生或冬青，一根用紫衫木或其它特殊木材制作的魔杖或节杖，一根从活树上折下的法杖或是一个包含神圣动物身上的羽毛、毛皮、骨头和牙齿组合成的图腾。德鲁伊能将这样的物品用作其施法的法器。 | AS40: 1gp | AT40: 0
...

Sheet 职业
B1: PHB | C1: XGE | D1: SCAG | E1: TCE | F1: EGtW | G1: BGG | H1: VGR | I1: FTD | T1: 主职业 | U1: 范型 | V1: 兼职1 | W1: 范型 | X1: 兼职2 | Y1: 范型 | Z1: 职业特性 | AA1: 范型 | AC1: 生命值成长 | AE1: 生命骰 | AF1: 期望值 | AH1: 职业 | AI1: 等级 | AJ1: 本职 | AK1: 子职 | AL1: 等级 | AN1: 等级 | AO1: 1环 | AP1: 2环 | AQ1: 3环 | AR1: 4环 | AS1: 5环 | AT1: 6环 | AU1: 7环 | AV1: 8环 | AW1: 9环 | AX1: 法术值 | AY1: 邪术师等级 | AZ1: 1环 | BA1: 2环 | BB1: 3环 | BC1: 4环 | BD1: 5环
B2: 0 | C2: 1 | D2: 2 | E2: 3 | F2: 4 | G2: 5 | H2: 6 | I2: 7 | J2: 8 | K2: 9 | L2: 10 | M2: 11 | N2: 12 | O2: 13 | P2: 14 | Q2: 15 | R2: 16 | T2: =#REF! -> #REF! | U2: =IFERROR(IF(VLOOKUP(T2,B3:R22,2,FALSE)=0,"",VLOOKUP(T2,B3:R22,2,FALSE)),"") | V2: =#REF! -> #REF! | W2: =IFERROR(IF(VLOOKUP(V2,B3:R22,2,FALSE)=0,"",VLOOKUP(V2,B3:R22,2,FALSE)),"") | X2: =#REF! -> #REF! | Y2: =IFERROR(IF(VLOOKUP(X2,B3:R22,2,FALSE)=0,"",VLOOKUP(X2,B3:R22,2,FALSE)),"") | Z2: =#REF! -> #REF! | AA2: =IFERROR(IF(VLOOKUP(Z2,B3:R22,2,FALSE)=0,"",VLOOKUP(Z2,B3:R22,2,FALSE)),"") | AC2: 法师 | AD2: 1d6 | AE2: =IFERROR(VLOOKUP(#REF!,AC2:AD14,2,FALSE),"") | AF2: =IFERROR(VLOOKUP(AE2,AC16:AD19,2,FALSE),0) -> 0 | AH2: 野蛮人 | AI2: =IFERROR(VLOOKUP(AH2,$AJ$2:$AL$4,3,0),0) -> 0 | AJ2: =IF(#REF!="",0,#REF!) -> #REF! | AK2: =IF(#REF!="",0,#REF!) -> #REF! | AL2: =IF(#REF!="",0,#REF!) -> #REF! | AN2: 0 | AY2: 0
A3: 1 | B3: 野蛮人 | C3: 狂战士 | D3: 图腾武者 | E3: 狂热者 | F3: 先祖守卫 | G3: 风暴先驱 | H3: 战狂 | I3: 狂野魔法道途 | J3: 野兽道途 | K3: 巨人道途 | U3: =IFERROR(IF(VLOOKUP(T2,B3:R22,3,FALSE)=0,"",VLOOKUP(T2,B3:R22,3,FALSE)),"") | W3: =IFERROR(IF(VLOOKUP(V2,B3:R22,3,FALSE)=0,"",VLOOKUP(V2,B3:R22,3,FALSE)),"") | Y3: =IFERROR(IF(VLOOKUP(X2,B3:R22,3,FALSE)=0,"",VLOOKUP(X2,B3:R22,3,FALSE)),"") | AA3: =IFERROR(IF(VLOOKUP(Z2,B3:R22,3,FALSE)=0,"",VLOOKUP(Z2,B3:R22,3,FALSE)),"") | AC3: 术士 | AD3: 1d6 | AE3: =IFERROR(VLOOKUP(#REF!,AC2:AD14,2,FALSE),"") | AF3: =IFERROR(VLOOKUP(AE3,AC16:AD19,2,FALSE),0) -> 0 | AH3: 吟游诗人 | AI3: =IFERROR(VLOOKUP(AH3,$AJ$2:$AL$4,3,0),0) -> 0 | AJ3: =IF(#REF!="",0,#REF!) -> #REF! | AK3: =IF(#REF!="",0,#REF!) -> #REF! | AL3: =IF(#REF!="",0,#REF!) -> #REF! | AN3: 1 | AO3: 2 | AX3: 4 | AY3: 1 | AZ3: 1
A4: 2 | B4: 吟游诗人 | C4: 逸闻学院 | D4: 勇气学院 | E4: 迷惑学院 | F4: 剑舞学院 | G4: 低语学院 | H4: 创造学院 | I4: 雄辩学院 | J4: 精魂学院 | U4: =IFERROR(IF(VLOOKUP(T2,B3:R22,4,FALSE)=0,"",VLOOKUP(T2,B3:R22,4,FALSE)),"") | W4: =IFERROR(IF(VLOOKUP(V2,B3:R22,4,FALSE)=0,"",VLOOKUP(V2,B3:R22,4,FALSE)),"") | Y4: =IFERROR(IF(VLOOKUP(X2,B3:R22,4,FALSE)=0,"",VLOOKUP(X2,B3:R22,4,FALSE)),"") | AA4: =IFERROR(IF(VLOOKUP(Z2,B3:R22,4,FALSE)=0,"",VLOOKUP(Z2,B3:R22,4,FALSE)),"") | AC4: 吟游诗人 | AD4: 1d8 | AE4: =IFERROR(VLOOKUP(#REF!,AC2:AD14,2,FALSE),"") | AF4: =IFERROR(VLOOKUP(AE4,AC16:AD19,2,FALSE),0) -> 0 | AH4: 牧师 | AI4: =IFERROR(VLOOKUP(AH4,$AJ$2:$AL$4,3,0),0) -> 0 | AJ4: =IF(#REF!="",0,#REF!) -> #REF! | AK4: =IF(#REF!="",0,#REF!) -> #REF! | AL4: =IF(#REF!="",0,#REF!) -> #REF! | AN4: 2 | AO4: 3 | AX4: 6 | AY4: 2 | AZ4: 2
A5: 3 | B5: 牧师 | C5: 知识领域 | D5: 生命领域 | E5: 光明领域 | F5: 自然领域 | G5: 风暴领域 | H5: 诡术领域 | I5: 战争领域 | J5: 锻造领域 | K5: 坟墓领域 | L5: 奥秘领域 | M5: 秩序领域 | N5: 和平领域 | O5: 暮光领域 | U5: =IFERROR(IF(VLOOKUP(T2,B3:R22,5,FALSE)=0,"",VLOOKUP(T2,B3:R22,5,FALSE)),"") | W5: =IFERROR(IF(VLOOKUP(V2,B3:R22,5,FALSE)=0,"",VLOOKUP(V2,B3:R22,5,FALSE)),"") | Y5: =IFERROR(IF(VLOOKUP(X2,B3:R22,5,FALSE)=0,"",VLOOKUP(X2,B3:R22,5,FALSE)),"") | AA5: =IFERROR(IF(VLOOKUP(Z2,B3:R22,5,FALSE)=0,"",VLOOKUP(Z2,B3:R22,5,FALSE)),"") | AC5: 牧师 | AD5: 1d8 | AH5: 德鲁伊 | AI5: =IFERROR(VLOOKUP(AH5,$AJ$2:$AL$4,3,0),0) -> 0 | AN5: 3 | AO5: 4 | AP5: 2 | AX5: 14 | AY5: 3 | BA5: 2
A6: 4 | B6: 德鲁伊 | C6: 大地结社 | D6: 月亮结社 | E6: 梦境结社 | F6: 牧人结社 | G6: 孢子结社 | H6: 星辰结社 | I6: 野火结社 | U6: =IFERROR(IF(VLOOKUP(T2,B3:R22,6,FALSE)=0,"",VLOOKUP(T2,B3:R22,6,FALSE)),"") | W6: =IFERROR(IF(VLOOKUP(V2,B3:R22,6,FALSE)=0,"",VLOOKUP(V2,B3:R22,6,FALSE)),"") | Y6: =IFERROR(IF(VLOOKUP(X2,B3:R22,6,FALSE)=0,"",VLOOKUP(X2,B3:R22,6,FALSE)),"") | AA6: =IFERROR(IF(VLOOKUP(Z2,B3:R22,6,FALSE)=0,"",VLOOKUP(Z2,B3:R22,6,FALSE)),"") | AC6: 德鲁伊 | AD6: 1d8 | AE6: 总等级 | AF6: =#REF!+#REF!+#REF! -> #REF! | AH6: 战士 | AI6: =IFERROR(VLOOKUP(AH6,$AJ$2:$AL$4,3,0),0) -> 0 | AK6: 奥法骑士 | AL6: =IF(AK2="奥法骑士",AL2,IF(AK3="奥法骑士",AL3,IF(AK4="奥法骑士",AL4,0))) -> #REF! | AN6: 4 | AO6: 4 | AP6: 3 | AX6: 17 | AY6: 4 | BA6: 2
A7: 5 | B7: 战士 | C7: 勇士 | D7: 战斗大师 | E7: 奥法骑士 | F7: 魔射手 | G7: 骑兵 | H7: 武士 | I7: 紫龙骑士 | J7: 回音骑士 | K7: 符文骑士 | L7: 灵能武士 | U7: =IFERROR(IF(VLOOKUP(T2,B3:R22,7,FALSE)=0,"",VLOOKUP(T2,B3:R22,7,FALSE)),"") | W7: =IFERROR(IF(VLOOKUP(V2,B3:R22,7,FALSE)=0,"",VLOOKUP(V2,B3:R22,7,FALSE)),"") | Y7: =IFERROR(IF(VLOOKUP(X2,B3:R22,7,FALSE)=0,"",VLOOKUP(X2,B3:R22,7,FALSE)),"") | AA7: =IFERROR(IF(VLOOKUP(Z2,B3:R22,7,FALSE)=0,"",VLOOKUP(Z2,B3:R22,7,FALSE)),"") | AC7: 武僧 | AD7: 1d8 | AE7: 首级 | AF7: =IFERROR(VLOOKUP(AE2,AC21:AD24,2,FALSE),0) -> 0 | AH7: 武僧 | AI7: =IFERROR(VLOOKUP(AH7,$AJ$2:$AL$4,3,0),0) -> 0 | AK7: 诡术师 | AL7: =IF(AK2="诡术师",AL2,IF(AK3="诡术师",AL3,IF(AK4="诡术师",AL4,0))) -> #REF! | AN7: 5 | AO7: 4 | AP7: 3 | AQ7: 2 | AX7: 27 | AY7: 5 | BB7: 2
A8: 6 | B8: 武僧 | C8: 散打宗 | D8: 暗影宗 | E8: 四象宗 | F8: 醉拳宗 | G8: 剑圣宗 | H8: 日魂宗 | I8: 永亡宗 | J8: 命流宗 | K8: 星我宗 | L8: 神龙宗 | U8: =IFERROR(IF(VLOOKUP(T2,B3:R22,8,FALSE)=0,"",VLOOKUP(T2,B3:R22,8,FALSE)),"") | W8: =IFERROR(IF(VLOOKUP(V2,B3:R22,8,FALSE)=0,"",VLOOKUP(V2,B3:R22,8,FALSE)),"") | Y8: =IFERROR(IF(VLOOKUP(X2,B3:R22,8,FALSE)=0,"",VLOOKUP(X2,B3:R22,8,FALSE)),"") | AA8: =IFERROR(IF(VLOOKUP(Z2,B3:R22,8,FALSE)=0,"",VLOOKUP(Z2,B3:R22,8,FALSE)),"") | AC8: 游荡者 | AD8: 1d8 | AH8: 圣武士 | AI8: =IFERROR(VLOOKUP(AH8,$AJ$2:$AL$4,3,0),0) -> 0 | AN8: 6 | AO8: 4 | AP8: 3 | AQ8: 3 | AX8: 32 | AY8: 6 | BB8: 2
A9: 7 | B9: 圣武士 | C9: 奉献之誓 | D9: 古贤之誓 | E9: 复仇之誓 | F9: 征服之誓 | G9: 救赎之誓 | H9: 王冠之誓 | I9: 荣耀之誓 | J9: 守望之誓 | U9: =IFERROR(IF(VLOOKUP(T2,B3:R22,9,FALSE)=0,"",VLOOKUP(T2,B3:R22,9,FALSE)),"") | W9: =IFERROR(IF(VLOOKUP(V2,B3:R22,9,FALSE)=0,"",VLOOKUP(V2,B3:R22,9,FALSE)),"") | Y9: =IFERROR(IF(VLOOKUP(X2,B3:R22,9,FALSE)=0,"",VLOOKUP(X2,B3:R22,9,FALSE)),"") | AA9: =IFERROR(IF(VLOOKUP(Z2,B3:R22,9,FALSE)=0,"",VLOOKUP(Z2,B3:R22,9,FALSE)),"") | AC9: 邪术师 | AD9: 1d8 | AE9: 全施法者 | AF9: =AI3+AI4+AI5+AI11+AI13 -> 0 | AH9: 游侠 | AI9: =IFERROR(VLOOKUP(AH9,$AJ$2:$AL$4,3,0),0) -> 0 | AN9: 7 | AO9: 4 | AP9: 3 | AQ9: 3 | AR9: 1 | AX9: 38 | AY9: 7 | BC9: 2
A10: 8 | B10: 游侠 | C10: 猎人 | D10: 驯兽师 | E10: 幽域追踪者 | F10: 边界行者 | G10: 怪物杀手 | H10: 集群牧者 | I10: 妖精漫游者 | J10: 龙兽守卫 | U10: =IFERROR(IF(VLOOKUP(T2,B3:R22,10,FALSE)=0,"",VLOOKUP(T2,B3:R22,10,FALSE)),"") | W10: =IFERROR(IF(VLOOKUP(V2,B3:R22,10,FALSE)=0,"",VLOOKUP(V2,B3:R22,10,FALSE)),"") | Y10: =IFERROR(IF(VLOOKUP(X2,B3:R22,10,FALSE)=0,"",VLOOKUP(X2,B3:R22,10,FALSE)),"") | AA10: =IFERROR(IF(VLOOKUP(Z2,B3:R22,10,FALSE)=0,"",VLOOKUP(Z2,B3:R22,10,FALSE)),"") | AC10: 奇械师 | AD10: 1d8 | AE10: 半施法者 | AF10: =ROUNDDOWN((AI8+AI9)/2,0) -> 0 | AH10: 游荡者 | AI10: =IFERROR(VLOOKUP(AH10,$AJ$2:$AL$4,3,0),0) -> 0 | AN10: 8 | AO10: 4 | AP10: 3 | AQ10: 3 | AR10: 2 | AX10: 44 | AY10: 8 | BC10: 2
A11: 9 | B11: 游荡者 | C11: 盗贼 | D11: 刺客 | E11: 诡术师 | F11: 调查员 | G11: 策士 | H11: 斥候 | I11: 游荡剑客 | J11: 鬼魅 | K11: 魂刃 | U11: =IFERROR(IF(VLOOKUP(T2,B3:R22,11,FALSE)=0,"",VLOOKUP(T2,B3:R22,11,FALSE)),"") | W11: =IFERROR(IF(VLOOKUP(V2,B3:R22,11,FALSE)=0,"",VLOOKUP(V2,B3:R22,11,FALSE)),"") | Y11: =IFERROR(IF(VLOOKUP(X2,B3:R22,11,FALSE)=0,"",VLOOKUP(X2,B3:R22,11,FALSE)),"") | AA11: =IFERROR(IF(VLOOKUP(Z2,B3:R22,11,FALSE)=0,"",VLOOKUP(Z2,B3:R22,11,FALSE)),"") | AC11: 战士 | AD11: 1d10 | AE11: 诡奥 | AF11: =IF(AF9=0,ROUNDUP((AL6+AL7)/3,0),ROUNDDOWN((AL6+AL7)/3,0)) -> #REF! | AH11: 术士 | AI11: =IFERROR(VLOOKUP(AH11,$AJ$2:$AL$4,3,0),0) -> 0 | AN11: 9 | AO11: 4 | AP11: 3 | AQ11: 3 | AR11: 3 | AS11: 1 | AX11: 57 | AY11: 9 | BD11: 3
A12: 10 | B12: 术士 | C12: 龙族血脉 | D12: 狂野魔法 | E12: 神圣之魂 | F12: 幽影魔法 | G12: 风暴术法 | H12: 畸变心智 | I12: 时械之魂 | J12: 月之术法 | U12: =IFERROR(IF(VLOOKUP(T2,B3:R22,12,FALSE)=0,"",VLOOKUP(T2,B3:R22,12,FALSE)),"") | W12: =IFERROR(IF(VLOOKUP(V2,B3:R22,12,FALSE)=0,"",VLOOKUP(V2,B3:R22,12,FALSE)),"") | Y12: =IFERROR(IF(VLOOKUP(X2,B3:R22,12,FALSE)=0,"",VLOOKUP(X2,B3:R22,12,FALSE)),"") | AA12: =IFERROR(IF(VLOOKUP(Z2,B3:R22,12,FALSE)=0,"",VLOOKUP(Z2,B3:R22,12,FALSE)),"") | AC12: 圣武士 | AD12: 1d10 | AH12: 邪术师 | AI12: =IFERROR(VLOOKUP(AH12,$AJ$2:$AL$4,3,0),0) -> 0 | AN12: 10 | AO12: 4 | AP12: 3 | AQ12: 3 | AR12: 3 | AS12: 2 | AX12: 64 | AY12: 10 | BD12: 3
A13: 11 | B13: 邪术师 | C13: 至高妖精 | D13: 邪魔宗主 | E13: 旧日支配者 | F13: 天界宗主 | G13: 咒剑士 | H13: 不朽者 | I13: 巨灵宗主 | J13: 深海意志 | K13: 死灵宗主 | U13: =IFERROR(IF(VLOOKUP(T2,B3:R22,13,FALSE)=0,"",VLOOKUP(T2,B3:R22,13,FALSE)),"") | W13: =IFERROR(IF(VLOOKUP(V2,B3:R22,13,FALSE)=0,"",VLOOKUP(V2,B3:R22,13,FALSE)),"") | Y13: =IFERROR(IF(VLOOKUP(X2,B3:R22,13,FALSE)=0,"",VLOOKUP(X2,B3:R22,13,FALSE)),"") | AA13: =IFERROR(IF(VLOOKUP(Z2,B3:R22,13,FALSE)=0,"",VLOOKUP(Z2,B3:R22,13,FALSE)),"") | AC13: 游侠 | AD13: 1d10 | AH13: 法师 | AI13: =IFERROR(VLOOKUP(AH13,$AJ$2:$AL$4,3,0),0) -> 0 | AN13: 11 | AO13: 4 | AP13: 3 | AQ13: 3 | AR13: 3 | AS13: 2 | AT13: 1 | AX13: 73 | AY13: 11 | BD13: 3
A14: 12 | B14: 法师 | C14: 防护学派 | D14: 咒法学派 | E14: 预言学派 | F14: 附魔学派 | G14: 塑能学派 | H14: 幻术学派 | I14: 死灵学派 | J14: 变化学派 | K14: 战争魔法 | L14: 剑咏者 | M14: 时间魔法 | N14: 重力魔法 | O14: 书士会 | U14: =IFERROR(IF(VLOOKUP(T2,B3:R22,14,FALSE)=0,"",VLOOKUP(T2,B3:R22,14,FALSE)),"") | W14: =IFERROR(IF(VLOOKUP(V2,B3:R22,14,FALSE)=0,"",VLOOKUP(V2,B3:R22,14,FALSE)),"") | Y14: =IFERROR(IF(VLOOKUP(X2,B3:R22,14,FALSE)=0,"",VLOOKUP(X2,B3:R22,14,FALSE)),"") | AA14: =IFERROR(IF(VLOOKUP(Z2,B3:R22,14,FALSE)=0,"",VLOOKUP(Z2,B3:R22,14,FALSE)),"") | AC14: 野蛮人 | AD14: 1d12 | AE14: 施法者等级 | AF14: =AF9+AF10+AF11 -> #REF! | AH14: 奇械师 | AI14: =IFERROR(VLOOKUP(AH14,$AJ$2:$AL$4,3,0),0) -> 0 | AN14: 12 | AO14: 4 | AP14: 3 | AQ14: 3 | AR14: 3 | AS14: 2 | AT14: 1 | AX14: 73 | AY14: 12 | BD14: 3
A15: 13 | B15: 奇械师 | C15: 炼金师 | D15: 魔炮师 | E15: 战地匠师 | F15: 装甲师 | U15: =IFERROR(IF(VLOOKUP(T2,B3:R22,15,FALSE)=0,"",VLOOKUP(T2,B3:R22,15,FALSE)),"") | W15: =IFERROR(IF(VLOOKUP(V2,B3:R22,15,FALSE)=0,"",VLOOKUP(V2,B3:R22,15,FALSE)),"") | Y15: =IFERROR(IF(VLOOKUP(X2,B3:R22,15,FALSE)=0,"",VLOOKUP(X2,B3:R22,15,FALSE)),"") | AA15: =IFERROR(IF(VLOOKUP(Z2,B3:R22,15,FALSE)=0,"",VLOOKUP(Z2,B3:R22,15,FALSE)),"") | AC15: 期望值 | AE15: 1环 | AF15: =IFERROR(VLOOKUP($AF$14,$AN$2:$AW$22,2,FALSE),"") | AN15: 13 | AO15: 4 | AP15: 3 | AQ15: 3 | AR15: 3 | AS15: 2 | AT15: 1 | AU15: 1 | AX15: 83 | AY15: 13 | BD15: 3
A16: 14 | U16: =IFERROR(IF(VLOOKUP(T2,B3:R22,16,FALSE)=0,"",VLOOKUP(T2,B3:R22,16,FALSE)),"") | W16: =IFERROR(IF(VLOOKUP(V2,B3:R22,16,FALSE)=0,"",VLOOKUP(V2,B3:R22,16,FALSE)),"") | Y16: =IFERROR(IF(VLOOKUP(X2,B3:R22,16,FALSE)=0,"",VLOOKUP(X2,B3:R22,16,FALSE)),"") | AA16: =IFERROR(IF(VLOOKUP(Z2,B3:R22,16,FALSE)=0,"",VLOOKUP(Z2,B3:R22,16,FALSE)),"") | AC16: 1d6 | AD16: 4 | AE16: 2环 | AF16: =IFERROR(VLOOKUP($AF$14,$AN$2:$AW$22,3,FALSE),"") | AI16: 1环 | AJ16: =IF(AF15+AH20=0,"",AF15+AH20) -> #VALUE! | AN16: 14 | AO16: 4 | AP16: 3 | AQ16: 3 | AR16: 3 | AS16: 2 | AT16: 1 | AU16: 1 | AX16: 83 | AY16: 14 | BD16: 3
A17: 15 | U17: =IFERROR(IF(VLOOKUP(T2,B3:R22,17,FALSE)=0,"",VLOOKUP(T2,B3:R22,17,FALSE)),"") | W17: =IFERROR(IF(VLOOKUP(V2,B3:R22,17,FALSE)=0,"",VLOOKUP(V2,B3:R22,17,FALSE)),"") | Y17: =IFERROR(IF(VLOOKUP(X2,B3:R22,17,FALSE)=0,"",VLOOKUP(X2,B3:R22,17,FALSE)),"") | AA17: =IFERROR(IF(VLOOKUP(Z2,B3:R22,17,FALSE)=0,"",VLOOKUP(Z2,B3:R22,17,FALSE)),"") | AC17: 1d8 | AD17: 5 | AE17: 3环 | AF17: =IFERROR(VLOOKUP($AF$14,$AN$2:$AW$22,4,FALSE),"") | AI17: 2环 | AJ17: =IF(AF16+AH21=0,"",AF16+AH21) -> #VALUE! | AN17: 15 | AO17: 4 | AP17: 3 | AQ17: 3 | AR17: 3 | AS17: 2 | AT17: 1 | AU17: 1 | AV17: 1 | AX17: 94 | AY17: 15 | BD17: 3
A18: 16 | AC18: 1d10 | AD18: 6 | AE18: 4环 | AF18: =IFERROR(VLOOKUP($AF$14,$AN$2:$AW$22,5,FALSE),"") | AI18: 3环 | AJ18: =IF(AF17+AH22=0,"",AF17+AH22) -> #VALUE! | AN18: 16 | AO18: 4 | AP18: 3 | AQ18: 3 | AR18: 3 | AS18: 2 | AT18: 1 | AU18: 1 | AV18: 1 | AX18: 94 | AY18: 16 | BD18: 3
A19: 17 | AC19: 1d12 | AD19: 7 | AE19: 5环 | AF19: =IFERROR(VLOOKUP($AF$14,$AN$2:$AW$22,6,FALSE),"") | AG19: 邪术师 | AI19: 4环 | AJ19: =IF(AF18+AH23=0,"",AF18+AH23) -> #VALUE! | AN19: 17 | AO19: 4 | AP19: 3 | AQ19: 3 | AR19: 3 | AS19: 2 | AT19: 1 | AU19: 1 | AV19: 1 | AW19: 1 | AX19: 107 | AY19: 17 | BD19: 4
A20: 18 | AC20: 首级 | AE20: 6环 | AF20: =IFERROR(VLOOKUP($AF$14,$AN$2:$AW$22,7,FALSE),"") | AG20: 1环 | AH20: =IFERROR(VLOOKUP($AI$12,$AY$2:$BD$22,2,FALSE),"") -> 0 | AI20: 5环 | AJ20: =IF(AF19+AH24=0,"",AF19+AH24) -> #VALUE! | AN20: 18 | AO20: 4 | AP20: 3 | AQ20: 3 | AR20: 3 | AS20: 3 | AT20: 1 | AU20: 1 | AV20: 1 | AW20: 1 | AX20: 114 | AY20: 18 | BD20: 4
A21: 19 | AC21: 1d6 | AD21: 2 | AE21: 7环 | AF21: =IFERROR(VLOOKUP($AF$14,$AN$2:$AW$22,8,FALSE),"") | AG21: 2环 | AH21: =IFERROR(VLOOKUP($AI$12,$AY$2:$BD$22,3,FALSE),"") -> 0 | AI21: 6环 | AJ21: =IF(AF20=0,"",AF20) | AN21: 19 | AO21: 4 | AP21: 3 | AQ21: 3 | AR21: 3 | AS21: 3 | AT21: 2 | AU21: 1 | AV21: 1 | AW21: 1 | AX21: 123 | AY21: 19 | BD21: 4
A22: 20 | AC22: 1d8 | AD22: 3 | AE22: 8环 | AF22: =IFERROR(VLOOKUP($AF$14,$AN$2:$AW$22,9,FALSE),"") | AG22: 3环 | AH22: =IFERROR(VLOOKUP($AI$12,$AY$2:$BD$22,4,FALSE),"") -> 0 | AI22: 7环 | AJ22: =IF(AF21=0,"",AF21) | AN22: 20 | AO22: 4 | AP22: 3 | AQ22: 3 | AR22: 3 | AS22: 3 | AT22: 2 | AU22: 2 | AV22: 1 | AW22: 1 | AX22: 133 | AY22: 20 | AZ22: ="" | BA22: ="" | BB22: ="" | BC22: ="" | BD22: 4
AC23: 1d10 | AD23: 4 | AE23: 9环 | AF23: =IFERROR(VLOOKUP($AF$14,$AN$2:$AW$22,10,FALSE),"") | AG23: 4环 | AH23: =IFERROR(VLOOKUP($AI$12,$AY$2:$BD$22,5,FALSE),"") -> 0 | AI23: 8环 | AJ23: =IF(AF22=0,"",AF22)
AC24: 1d12 | AD24: 5 | AE24: 法术值 | AF24: =IFERROR(VLOOKUP($AF$14,$AN$2:$AX$22,11,FALSE),"") | AG24: 5环 | AH24: =IFERROR(VLOOKUP($AI$12,$AY$2:$BD$22,6,FALSE),"") -> 0 | AI24: 9环 | AJ24: =IF(AF23=0,"",AF23)
AX25: 列1 | AY25: 列2 | AZ25: 最小数据行 | BA25: 最大数据行
AW26: =IF(#REF!<>"",#REF!,"") -> #REF! | AX26: =IFERROR(VLOOKUP(AW26,A29:E192,2,FALSE),"") | AY26: =IFERROR(VLOOKUP(AW26,A29:E192,3,FALSE),"") | AZ26: =IFERROR(VLOOKUP(AW26,A29:E192,4,FALSE),"") | BA26: =IFERROR(VLOOKUP(AW26,A29:E192,5,FALSE),"")
AW27: =IF(#REF!<>"",#REF!,"") -> #REF! | AX27: 0v0? | AY27: 0v0? | AZ27: =IFERROR(VLOOKUP(AW27,A29:E192,4,FALSE),"") | BA27: =IFERROR(VLOOKUP(AW27,A29:E192,5,FALSE),"")
B28: 名称列 | C28: 描述列 | D28: 最小数据行 | E28: 最大数据行
A29: 野蛮人 | B29: 1 | C29: 2 | D29: 1 | E29: 19 | H29: 1 | I29: 2 | J29: 3 | K29: 4 | L29: 5 | M29: 6 | N29: 7 | O29: 8 | P29: 9 | Q29: 10 | R29: 11 | S29: 12 | T29: 13 | U29: 14 | V29: 15 | W29: 16 | X29: 17 | Y29: 18 | Z29: 19 | AA29: 20 | AB29: 21 | AC29: 22 | AD29: 23 | AE29: 24 | AF29: 25 | AG29: 26 | AH29: 27 | AI29: 28 | AJ29: 29 | AK29: 30 | AL29: 31 | AM29: 32 | AN29: 33 | AO29: 34 | AP29: 35 | AQ29: 36 | AR29: 37 | AS29: 38 | AT29: 39 | AU29: 40 | AW29: 0 | AX29: 名称 | AY29: 描述 | AZ29: 增值
A30: 吟游诗人 | B30: 3 | C30: 4 | D30: 1 | E30: 22 | H30: 野蛮人 | J30: 吟游诗人 | L30: 牧师 | N30: 德鲁伊 | P30: 战士 | R30: 武僧 | T30: 圣武士 | V30: 游侠 | X30: 游荡者 | Z30: 术士 | AB30: 邪术师 | AD30: 法师 | AF30: 奇械师 | AH30: ？？？ | AJ30: ？？？ | AL30: ？？？ | AN30: ？？？ | AP30: ？？？ | AR30: ？？？ | AT30: ？？？ | AW30: =IFERROR(IF(AW29+1>BA26,IF(AW29+1>BA26,IF(AZ27+AZ29>BA27,"",AZ27+AZ29)),AW29+1),"") -> 1 | AX30: =IFERROR(INDEX(H31:AU181,AW30,AX26),"") | AY30: =IFERROR(INDEX(H31:AU181,AW30,AY26),"") | AZ30: =IFERROR(IF(AW29+1>BA26,AZ29+1,0),"") -> 0 | BB30: =IF(#REF!="","",#REF!) -> #REF! | BC30: =IFERROR(VLOOKUP(BB30,AX30:AY129,2,FALSE),"")
A31: 牧师 | B31: 5 | C31: 6 | D31: 1 | E31: 19 | G31: 1 | H31: 护甲熟练 | I31: 轻甲、中甲、盾牌 | J31: 护甲熟练 | K31: 轻甲 | L31: 护甲熟练 | M31: 轻甲、中甲、盾牌 | N31: 护甲熟练 | O31: 轻甲、中甲、盾牌（德鲁伊不能装备或使用金属质的护甲和盾） | P31: 护甲熟练 | Q31: 全部护甲、盾牌 | R31: 护甲熟练 | S31: 无 | T31: 护甲熟练 | U31: 所有护甲和盾牌 | V31: 护甲熟练 | W31: 轻甲、中甲、盾牌 | X31: 护甲熟练 | Y31: 轻甲 | Z31: 护甲熟练 | AA31: 无 | AB31: 护甲熟练 | AC31: 轻甲 | AD31: 护甲熟练 | AE31: 无 | AF31: 护甲熟练 | AG31: 轻甲、中甲、盾牌 | AW31: =IFERROR(IF(AW30+1>BA26,IF(AW30+1>BA26,IF(AZ27+AZ30>BA27,"",AZ27+AZ30)),AW30+1),"") -> 2 | AX31: =IFERROR(INDEX(H31:AU181,AW31,AX26),"") | AY31: =IFERROR(INDEX(H31:AU181,AW31,AY26),"") | AZ31: =IFERROR(IF(AW30+1>BA26,AZ30+1,0),"") -> 0 | BB31: =IF(#REF!="","",#REF!) -> #REF! | BC31: =IFERROR(VLOOKUP(BB31,AX30:AY129,2,FALSE),"")
A32: 德鲁伊 | B32: 7 | C32: 8 | D32: 1 | E32: 19 | G32: 2 | H32: 武器熟练 | I32: 简易武器、军用武器 | J32: 武器熟练 | K32: 简易武器、手弩、长剑、刺剑、短剑 | L32: 武器熟练 | M32: 简易武器 | N32: 武器熟练 | O32: 短棒、匕首、飞镖、标枪、硬头锤、长棍、弯刀、镰刀、投石索、矛 | P32: 武器熟练 | Q32: 简易武器、军用武器 | R32: 武器熟练 | S32: 简易武器、短剑 | T32: 武器熟练 | U32: 简易武器和军用武器 | V32: 武器熟练 | W32: 简易武器、军用武器 | X32: 武器熟练 | Y32: 简易武器、手弩、长剑、刺剑、短剑 | Z32: 武器熟练 | AA32: 匕首、飞镖、投石索、长棍、轻弩 | AB32: 武器熟练 | AC32: 简易武器 | AD32: 武器熟练 | AE32: 匕首、飞镖、投石索、长棍、轻弩 | AF32: 武器熟练 | AG32: 简易武器 | AW32: =IFERROR(IF(AW31+1>BA26,IF(AW31+1>BA26,IF(AZ27+AZ31>BA27,"",AZ27+AZ31)),AW31+1),"") -> 3 | AX32: =IFERROR(INDEX(H31:AU181,AW32,AX26),"") | AY32: =IFERROR(INDEX(H31:AU181,AW32,AY26),"") | AZ32: =IFERROR(IF(AW31+1>BA26,AZ31+1,0),"") -> 0 | BB32: =IF(#REF!="","",#REF!) -> #REF! | BC32: =IFERROR(VLOOKUP(BB32,AX30:AY129,2,FALSE),"")
A33: 战士 | B33: 9 | C33: 10 | D33: 1 | E33: 12 | G33: 3 | H33: 工具熟练 | I33: 无 | J33: 工具熟练 | K33: 自选三种乐器 | L33: 工具熟练 | M33: 无 | N33: 工具熟练 | O33: 草药工具 | P33: 工具熟练 | Q33: 无 | R33: 工具熟练 | S33: 选择一种工匠工具或一种乐器 | T33: 工具熟练 | U33: 无 | V33: 工具熟练 | W33: 无 | X33: 工具熟练 | Y33: 盗贼工具 | Z33: 工具熟练 | AA33: 无 | AB33: 工具熟练 | AC33: 无 | AD33: 工具熟练 | AE33: 无 | AF33: 工具熟练 | AG33: 盗贼工具、修补工具、其他一种你选择的工匠工具 | AW33: =IFERROR(IF(AW32+1>BA26,IF(AW32+1>BA26,IF(AZ27+AZ32>BA27,"",AZ27+AZ32)),AW32+1),"") -> 4 | AX33: =IFERROR(INDEX(H31:AU181,AW33,AX26),"") | AY33: =IFERROR(INDEX(H31:AU181,AW33,AY26),"") | AZ33: =IFERROR(IF(AW32+1>BA26,AZ32+1,0),"") -> 0 | BB33: =IF(#REF!="","",#REF!) -> #REF! | BC33: =IFERROR(VLOOKUP(BB33,AX30:AY129,2,FALSE),"")
A34: 武僧 | B34: 11 | C34: 12 | D34: 1 | E34: 29 | G34: 4 | H34: 狂暴 | I34: 你带着原初的狂怒作战。你可以在自己回合内以一个附赠动作进入狂暴。 狂暴持续期间，只要你未着装重甲就获得以下增益： • 你进行力量检定和力量豁免时具有优势。 • 你用力量值发动近战武器攻击时的伤害掷骰获得加值。此加值随你的野蛮人等级提升而增加，具体见“野蛮人职业表”中“狂暴伤害”一栏。 • 你拥有钝击，穿刺和挥砍伤害的抗性。 拥有施法能力的角色无法在狂暴持续期间施展法术或进行法术专注。 你的狂暴状态维持1分钟。如果你在狂暴其间陷入昏迷，或者，如果你从自己上回合结束开始到本回合结束时都未攻击任何敌对生物也未受到伤害，则狂暴提前结束。你也可以在自己回合里以一个附赠动作主动结束狂暴状态。 “野蛮人职业表”中根据你的野蛮人等级给出了相应的狂暴次数。如果你用光了这些次数，则必须完成一次长休才能再次使用狂暴。 | J34: 施法 | K34: 你习得以音乐为媒介随意解构、分解，再重新构造现实的方法。 你的法术是融入你纷繁奏乐中的音符，也是你以各种形式谱奏的魔法乐章。 | L34: 施法 | M34: 你作为神圣力量的导体得以施展牧师法术。 | N34: 德鲁伊语 | O34: 你习得德鲁伊语——即一种德鲁伊间的秘密语言。 你可以说这门语言并用它留下隐藏的信息。 懂得这门语言的人（包括你自己）会自动注意到此信息，而不懂此语言的人通过一次DC15的感知（察觉）检定后可以注意到其存在，不过不能用非魔法手段读懂。 | P34: 战斗风格 | Q34: 你专精于一种战斗风格，并从下列选项中选择。 另外，即使你有多次选择战斗风格的机会，也不能多次选择同一个战斗风格。 箭术：你使用远程武器进行攻击检定时具有+2加值。 防御：着装护甲时，你的AC获得+1加值。 对决：单手持用一把近战武器，且并未同时持用其他武器时，你用该武器攻击的伤害掷骰获得+2加值。 巨武器战斗：双手持用一把近战武器发动攻击时，如果你的伤害掷骰掷出1或2，则可以选择重掷。不过哪怕其仍是1或2，你都必须接受重掷的数值。此外，该武器必须具有双手或两用属性。 守护：当某个你能看见的生物攻击你身边5尺内除你之外的目标时，你可以用反应迫使该攻击的攻击检定具有劣势。此时你必须持用盾牌。 双武器战斗：使用两把武器战斗时，你可以将相应属性调整值加到第二次攻击的伤害上。 | R34: 无甲防御 | S34: 第1级起，未着装任何护甲也没持用盾牌时，你的AC值等于10＋你的敏捷调整值＋你的感知调整值。 | T34: 神圣感知 | U34: 强大的邪恶存在于你有如带毒的香气，而强大的善良光环于你则如仙乐般悠扬。 你可以使用一个动作扩展你的意识，以侦测此类势力。 直到你下回合结束前，你可以对身边60尺范围内进行感测，任何未对你处在全身掩护状态的天界生物、邪魔或不死生物都将被你定位。 你感应到范围内生物的种类（天界生物、邪魔、不死生物），不过并不能精确指明。 在同样的范围内，你也可以侦测任何受到圣居一类的法术祝福或亵渎的地点或物件。 该特性的可用次数等于1＋你的魅力调整值。 而已消耗的特性使用次数，则可以通过完成一次长休进行恢复。 | V34: 宿敌 | W34: 第1级起，你针对一种特定类型敌人的研究令你有着充足的经验用以追踪、狩猎乃至与之交流。 从下列种类中选择其一作为宿敌：异怪、野兽、天界生物、构装生物、龙、元素生物、精类生物、邪魔、巨人、怪兽、泥怪、植物、不死生物。 或者作为另一种方案，你也可以选择两个类人生物种族（例如豺狼人和兽人）作为宿敌。 追踪宿敌时，你的感知（求生）检定，以及回想关于宿敌信息时进行的智力检定具有优势。 获得该特性时，如果你选择的宿敌具有语言能力，则你还可以学会宿敌所知晓的一门语言。 第6和第14级时，你将分别获得一个额外的宿敌以及相关语言。 另外，随着等级的提升，你所选择的宿敌应该与你在冒险中所遭遇怪物的种类层次相符。 | X34: 专精 | Y34: 第1级起，你选择两个已有技能熟练项，或者一个技能熟练项和盗贼工具熟练项。 此后你进行该项目的检定时，可以使用双倍的熟练加值。 第6级时，你可以再选择另外两个已有的技能熟练项（或盗贼工具熟练项）从该特性中获益。 | Z34: 施法 | AA34: 过去的一个事件激发了你体内先辈的血脉，为你烙上了奥法力量的坚固印记。 这股起源于某种存在的魔力驱动着你的法术能力。 | AB34: 契约魔法 | AC34: 你的法术力量源于你的奥秘研究和宗主的魔法馈赠。 | AD34: 施法 | AE34: 作为一名奥术魔法的研习者，你拥有一本自己的法术书。 书中所包含的法术隐约透露着你真正的力量。 | AF34: 魔法工艺 | AG34: 在第1级，你将学习如何在平凡的物品中注入魔法的火花。 要使用这个能力，你必须手持盗贼工具，或工匠工具。 然后花费一个动作触摸一个微小的非魔法物体，从以下魔法属性中选择一个赋予它： 该物体提供5尺半径的明亮照明，以及该范围外5尺范围的微光照明。 无论何时，只要该物品被生物触碰，就会发出可在10英尺外听到的录音信息，录入的信息在你将此属性赋予对象时决定，且时长不可超过6秒。 物品不断地发出一种气味或一种非语言的声音（风声、浪声、鸟叫或类似的声音），这一现象最多能传播10英尺远。 一个静态的视觉效果出现在物体的表面上，这个效果可以是一幅图片，最多25个单词的文本，线条和形状，或者这些元素的混合，如你所愿。 所选的魔法属性持续时间无限。你能够以一个动作触摸对象来消除这一魔法属性。 你能够通过此特性将魔力赋予多个物品，每次使用该特性时都需要触摸一个物品，并且单个物品一次只能承载一种魔法属性。 你能够使用该特性影响的物品的最大数量等于你的智力调整值（最少一个物品）。 如果你试图超过最大值，最老的魔法属性将立即结束，然后新的魔法属性生效。 | AW34: =IFERROR(IF(AW33+1>BA26,IF(AW33+1>BA26,IF(AZ27+AZ33>BA27,"",AZ27+AZ33)),AW33+1),"") -> 5 | AX34: =IFERROR(INDEX(H31:AU181,AW34,AX26),"") | AY34: =IFERROR(INDEX(H31:AU181,AW34,AY26),"") | AZ34: =IFERROR(IF(AW33+1>BA26,AZ33+1,0),"") -> 0 | BB34: =IF(#REF!="","",#REF!) -> #REF! | BC34: =IFERROR(VLOOKUP(BB34,AX30:AY129,2,FALSE),"")
A35: 圣武士 | B35: 13 | C35: 14 | D35: 1 | E35: 24 | G35: 5 | H35: 无甲防御 | I35: 未着装任何护甲时，你的AC等于10＋你的敏捷调整值＋你的体质调整值。使用盾牌不会影响你从此特性获益。 | J35: 戏法 | K35: 第1级时，你从诗人法术列表中选择两个戏法作为已知法术。 在获得更高诗人等级后你还可以习得其它的戏法，具体数量见“吟游诗人职业表”中“已知戏法”一栏。 | L35: 戏法 | M35: 第1级时，你选择三个牧师法术列表中的戏法作为已知法术。 在获得更高的牧师等级后你还可以习得其它的戏法，具体数据参见“牧师职业表”中“已知戏法”一栏。 | N35: 施法 | O35: 你掌握自然世界的神圣本质，并依你的意志施展法术对其进行重塑。 | P35: 战斗风格选项 | Q35: 从1级起，当你在选择战斗风格时，下列选项加入你的可选战斗风格中。 盲斗：你获得10尺盲视，在10尺范围内，你可以看见除了处于全遮掩后的任何东西，哪怕你正在被目盲或是在黑暗之中，另外，你可以看见该范围内的未对你成功躲藏的隐形生物。 卓越技巧：你从战斗大师武术范型的战技列表中习得一项战技，如果该战技需要豁免，则豁免DC为8+你的熟练加值+你的力量或敏捷调整值（由你选择）。 你获得一个d6的卓越骰（此卓越骰与任何你能够其他方式获得的卓越骰累计），此卓越骰可用于启动你的战技，卓越骰一经使用即消耗，并在完成一次短休或长休后恢复。 投掷武器战斗：你可以在使用一件带有投掷属性武器进行进攻时，将那件武器作为攻击的一部分而拔出，另外，在你以一件投掷武器于远程攻击中命中对手时，你的伤害掷骰+2。 徒手战斗：你的徒手打击可以造成1d6+你力量调整值的钝击伤害，如果你没有手持任何武器或盾牌进行攻击，伤害骰从d6变成d8， 每个你的回合开始时，你可以对被你擒抱的生物造成1d4钝击伤害。 | R35: 武艺 | S35: 第1级时，你修行的武艺让你使用徒手打击和武僧武器时得心应手。 武僧武器包括短剑和所有不含双手与重型属性的简易近战武器。 未着装任何护甲也没持用盾牌时，如果你徒手或只持用武僧武器，则你发动的攻击拥有下列增益： 你使用徒手打击或武僧武器进行攻击时，可以用敏捷值代替力量值进行攻击检定和伤害掷骰。 你使用徒手打击或武僧武器进行攻击时，可以选择用d4骰代替原本的伤害掷骰。该骰子将随武僧职业等级的提升而增大，具体数据见“武僧职业表”中“武艺”一栏。 你使用徒手打击或武僧武器执行攻击动作时，可以在自己回合内以附赠动作发动一次徒手打击。 例如，你执行攻击动作并使用长棍发动攻击时，若你本轮没有执行任何附赠动作，则可以用附赠动作来发动一次徒手打击。 某些宗派的武僧会使用一些奇异的武僧武器，比如铁链连接的两根短棒（双截棍），或者带直刃的镰刀（单镰）。 无论你使用什么武器，其属性数据都参考与其相似的常规武器属性数据。 具体的武器数据见第5章。 | T35: 圣疗 | U35: 你的触碰溢满祝福，可以医治伤口。 你获得一个治疗能量池，其内的治疗能量在每次完成长休后自动补满。 治疗能量池储备的可恢复生命值总值等于你的圣武士职业等级×5。 你可以用一个动作触碰一个生物，并抽取治疗能量池中的能量恢复该生物的生命值，其恢复量最多等于你治疗能量池中剩余的治疗量。 此外，你也可以使用5点治疗量治愈目标生物身上的一种疾病，或者祛除一种中毒效应。 你可以在一次圣疗中治愈复数的疾病并祛除复数的毒素，但你需要为每一种疾病和毒素分别支付治疗量。 该职业特性对不死生物和构装生物无效。 | V35: 夙敌 | W35: 从1级起（替换宿敌并能够对屠灭众敌起效），当你以一次攻击掷骰命中一个生物时，你可以呼唤你与自然的神秘羁连以将目标标记为你的夙敌，持续一分钟或直到你失去专注(如同你在专注一道法术)。 你在你的回合内第一次命中你的夙敌并对其造成伤害，且你正在标记它时，你可以造成额外的1d4点伤害。 你可以使用同等于你的熟练加值次该特性来标记你的夙敌，你在完成一次长休后恢复所有已使用的次数。 这个特性的额外伤害在你达到特定等级时会增加：6级时1d6，14级时1d8。 | X35: 偷袭 | Y35: 第1级起，你就知道如何精确地攻击分心的敌人。 每当你的攻击命中一个生物时，如果该攻击的攻击检定带有优势，则可以造成额外1d6的伤害。 该伤害每回合可以产生一次，且造成伤害的攻击必须使用带灵巧属性的武器或远程武器。 如果目标生物身边5尺内还有其他与之对敌者，且该对敌者并未处于失能状态，则只要你的攻击检定没有劣势，就可以发动偷袭。 你的偷袭伤害也将会随游荡者职业等级的提升而提高，其具体数值见“游荡者职业表”。 | Z35: 戏法 | AA35: 第1级时，你从术士法术列表里选择四个戏法作为已知法术。 在获得更高的术士等级后你还可以习得其它的戏法，具体数量见“术士职业表”中“已知戏法”一栏。 | AB35: 戏法 | AC35: 你从邪术师法术列表中选择两个戏法作为已知法术。 在获得更高的邪术师等级后你还可以习得其它的戏法，具体数据见“邪术师职业表”中“已知戏法”一栏。 | AD35: 戏法 | AE35: 第1级时，你从法师法术列表中选择三个戏法作为已知法术。 在获得更高的法师等级后你还可以习得其它的戏法，具体数量参见“法师职业表”中“已知戏法”一栏。 | AF35: 技艺的魔法 | AG35: 身为一名奇械师，你在施法时使用工具，当描述你的施法时，请想想你是如何使用一个工具来执行这个法术效果的。 如果你使用炼金工具来施展疗伤术，你可以很快的制造出药膏。 如果你用修补工具来施展，你可能会拿出一个微型机械蜘蛛来缝合伤口。 当你施放毒液喷溅时，你可以喷射出有毒的化学物质，或者使用一根喷射毒液的魔杖。 法术的效果和其他的施法者职业是一样，但是你的施法方法是特殊的。 同样的原则也适用于你准备法术的时候，作为一名奇械师，你不需要学习魔法书，也不需要祈祷去准备你的魔法。 你需要使用工具来制造用于产生效果的特定物品，如果你用电爪替换疗伤术，你可能会破坏你用来治疗的设备，并用它的部件制造一个攻击性的物品——这可能是一只能够让你引导冲击性能量的长手套。 这些细节不会以任何方式限制你，也不会给你带来任何好处，你不需要证明你是如何使用工具来施展法术的，但是创造性地描述你的施法是一种能够让你从其他施法者中脱颖而出的有趣方法。 | AW35: =IFERROR(IF(AW34+1>BA26,IF(AW34+1>BA26,IF(AZ27+AZ34>BA27,"",AZ27+AZ34)),AW34+1),"") -> 6 | AX35: =IFERROR(INDEX(H31:AU181,AW35,AX26),"") | AY35: =IFERROR(INDEX(H31:AU181,AW35,AY26),"") | AZ35: =IFERROR(IF(AW34+1>BA26,AZ34+1,0),"") -> 0 | BB35: =IF(#REF!="","",#REF!) -> #REF! | BC35: =IFERROR(VLOOKUP(BB35,AX30:AY129,2,FALSE),"")
A36: 游侠 | B36: 15 | C36: 16 | D36: 1 | E36: 25 | G36: 6 | H36: 鲁莽攻击 | I36: 第2级起，你可以抛弃一切防御的执念进行狂乱的攻击。你在自己回合内发动第一次攻击时，可以选择发动鲁莽攻击。 使用此特性后，你本回合内所有使用力量值发动的近战武器攻击具有优势。此后，所有对你发动的攻击检定也将具有优势，且该优势持续存在至你的下个回合。 | J36: 法术位 | K36: “吟游诗人职业表”中记录了你可用以施展诗人法术的1环及更高环阶法术位数量。 施展诗人法术时，你必须同时消耗其对应环阶的法术位。 已消耗的法术位可在完成长休后恢复。 | L36: 法术的准备与施展 | M36: “牧师职业表”里记录了你用以施展牧师法术的1环及更高环阶法术位数量。 施展某个牧师法术时，你必须同时消耗其对应环阶的法术位。 已消耗的法术位可在完成长休后恢复。 你可以准备牧师法术列表中所有符合当前施展条件的法术。 准备法术时，你所准备法术的总数等于你的感知调整值＋你的牧师职业等级（最少可以准备一个）。 另外，你只能准备已经获得相应环阶法术位的法术。 例如，作为一名3级牧师时，你拥有四枚1环法术位和两枚2环法术位。假如你的感知为16，则你的准备法术列表可以囊括总共六个1环或2环法术的组合。如果你准备了1环法术疗伤术cure wounds，则你可以使用1环或者2环的法术位来施展它。另外，已施展的法术并不会从你的准备列表中移除。 你可以在完成长休后改变你的准备法术列表。 准备新的牧师法术列表时，你要再花时间进行祈祷和冥想。 准备时，你要为你列表上每个法术的每个环阶都花费至少1分钟时间。 | N36: 戏法 | O36: 第1级时，你选择两项德鲁伊法术列表中的戏法作为已知法术。 在获得更高的德鲁伊等级后你还可以习得其它的戏法，具体数据参见“德鲁伊职业表”中“已知戏法”一栏。 | P36: 回气 | Q36: 你拥有少量精力储备可用来保护自己免受伤害。 你可以在自己回合内用一个附赠动作恢复生命值，其总值为1d10＋你的战士职业等级。 你必须完成一次短休或长休才能再次使用该特性。 | R36: 气 | S36: 第2级起，你掌握一股名为气的神秘能量。 此后你将拥有一定数量的气作为储备。 而气的储备量由你的武僧等级决定，具体数值见“武僧职业表”中“气”一栏。 你可以消耗气以行使各种特性。 一开始你掌握三种特性：疾风连击，坚强防御，飞檐走壁。 此后，随着等级的提升你将习得更多的特性。 消耗掉的气必须在你短休或长休时完成至少30分钟的冥想，才能重获所有消耗掉的气值。 某些特性需要目标进行豁免检定来抵抗你特性造成的效应。 其豁免DC如下： 气豁免DC＝8＋你的熟练加值＋你的感知调整值 | T36: 战斗风格 | U36: 第2级起，你将精进于一种战斗风格，从下列选项中选择其一。 另外，即使你有多次选择战斗风格的机会，也不能重复选择同一个战斗风格。 防御：着装护甲时，你的AC获得+1加值。 对决：单手持用一把近战武器，且并未同时持用其他武器时，你使用该武器进行攻击的伤害掷骰获得+2加值。 巨武器战斗：双手持用一把近战武器发动攻击时，若你的伤害掷骰掷出1或2，则可以选择重掷。 不过哪怕其仍是1或2，你都必须接受重掷的数值。 此外，该武器必须具有双手或两用属性。 守护：当某个你能看见的生物攻击你身边5尺内除你之外的目标时，你可以用反应迫使该攻击的攻击检定具有劣势。 你必须持用盾牌以实现该效果。 | V36: 自然探索者 | W36: 你对某种自然环境特别熟悉，并适应了在其中行走及生存。 从下列类别中选择一种偏爱地形：极地、海岸、荒漠、丛林、草原、山地、沼泽或幽暗地。 当你进行与偏好地形相关的智力或感知检定时，如果你拥有该技能的熟练项，则在检定时加入双倍熟练加值。 当你在偏好地形上移动一小时或更长时间时，你获得以下增益： 你的队伍旅行时不会因困难地形而变慢 除非受魔法效应影响，否则你的队伍不会迷路 旅行时，即使你进行另一项活动（如觅食、导航或追踪），仍能对危险保持警觉 独自旅行时，你能够保持隐匿状态以正常步调移动 觅食时，你会发现两倍的食物 追踪其他生物时，你还能了解他们的确切数量、体型以及离开踪迹的时间 你在第6级和第10级时将分别获得一个额外的偏好地形。 | X36: 盗贼黑话 | Y36: 作为一名游荡者，你在平时的练习中学会了盗贼间的黑话。 盗贼黑话是一门混合了土话、术语和密语的秘密语言，掌握这门语言后，你可以在平时对话中不落痕迹的加入隐藏信息。 而只有另一个懂盗贼黑话的生物才能看懂这些隐藏信息。 不过这种交流方式需要花费四倍于直接交流所需要的时间。 另外，你还习得一套用以传达简单短小信息的秘密符文和标识。 它能发布的内容诸如某地区是否危险，是否受盗贼公会管辖，附近是否有战利品，附近的人是否好主顾或者路上是否有安全的房屋以供庇护。 | Z36: 法术位 | AA36: “术士职业表”中记录了你用以施展你术士法术的1环及更高环阶法术位数量。 施展某个术士法术时，你必须同时消耗其对应环阶的法术位。 已消耗的法术位可在完成长休后恢复。 例如，若你已知1环法术燃烧之手burning hands，并且拥有一枚可用的1环法术位和一枚可用的2环法术位，则这两枚法术位都可以用来施展该法术。 | AB36: 法术位 | AC36: “邪术师职业表”里记录了你可用以施展邪术师法术的1环至5环法术位数量。 表格中还记录了法术位对应的法术环阶，且你所有的法术位都属于同一环阶。 施展1环或更高环阶的邪术师法术时，都需要消耗一枚法术位。 已消耗的法术位可在完成长休或短休后恢复。 例如，达到第5级时，你总共具有两枚3环法术位。 你施展1环法术巫术箭时，必须消耗消耗这些法术位其中之一，并把它作为一个3环法术施放。 | AD36: 你的法术书 | AE36: 你在等级提升时加入法术书中的法师法术，体现了你的奥术研究成果，同时也代表你对多元宇宙本质的认知的新突破。 你也许会在冒险过程中发现其他的法术。 例如，你可能在一个邪恶法师的箱子里发现了一张记载有法术的卷轴，或者在一个上古图书馆中发现了灰尘覆盖的卷册。 将法术抄入法术书：当你发现一道1环或更高环阶的法师法术时，你可以将其抄入你的法术书中，前提是，你必须能够准备该法术，且也有时间去解读和复制它。 抄写法术时，你必须先重构该法术的基础式，然后解读抄写该法术的法师所使用的独特符号系统。 你必须反复练习这个法术，直至完全理解其所需的咒语和手势，最后用再用你自己的符号系统将之抄入法术书。 这个过程将消耗每法术环阶2小时的时间和每法术环阶50gp的资金。 这笔开销代表你在练习这个法术的过程中消耗的材料成分，还有抄录法术所需的上好的墨水。 当你花费了这一笔时间和金钱后，你就可以如同准备其他法术一般准备这个法术了。 替换法术书：你可以把法术从你的法术书抄到另一本书上——例如，你打算为你的法术书做一个备份时，就可以这么做。 这个进程和将新法术抄入法术书相似，但更快也更简单，因为你早已理解了你自己的符号系统，也知道如何施展这个法术。 这时，你只需要花费每环阶1小时和每环阶10gp的花费。 如果你弄丢了法术书，你也可以用相同的流程将你准备的法术抄入一本新法术书中。 而要填满法术书的其余部分就需要你自己去寻找新的法术了。 所以，很多法师都喜欢在安全的地方保存好备份的法术书。 法术书外观：你的法术书是一本独特的法术合集，其上有着独特的使用痕迹和空白页。 它可以是导师赠予的简洁实用的皮册；或是在远古图书馆中发现的华丽镶边书册；甚至可以是在你遭遇意外后，松散的订在一起的一堆手稿。 | AF36: 施法 | AG36: 你已经学习了魔法的工作原理，知道如何引导魔法进入物体，以及如何唤醒魔法。 因此，你获得了有限的施法能力，在旁观者看来，你不会用传统的方式施法——你看起来好像在通过各种物品创造奇迹。 | AW36: =IFERROR(IF(AW35+1>BA26,IF(AW35+1>BA26,IF(AZ27+AZ35>BA27,"",AZ27+AZ35)),AW35+1),"") -> 7 | AX36: =IFERROR(INDEX(H31:AU181,AW36,AX26),"") | AY36: =IFERROR(INDEX(H31:AU181,AW36,AY26),"") | AZ36: =IFERROR(IF(AW35+1>BA26,AZ35+1,0),"") -> 0 | BB36: =IF(#REF!="","",#REF!) -> #REF! | BC36: =IFERROR(VLOOKUP(BB36,AX30:AY129,2,FALSE),"")
